Workbook

Sheet Dashboard
A1: Data Engineering Learning Tracker
A2: Overall progress dashboard — auto-calculated from each topic sheet
A4: Module | B4: Total Topics | C4: Completed | D4: In Progress | E4: Not Started | F4: % Complete
A5: SQL | B5: =COUNTA(SQL!$B$5:$B$60) | C5: =COUNTIF(SQL!$E$5:$E$60,"Completed") | D5: =COUNTIF(SQL!$E$5:$E$60,"In Progress") | E5: =COUNTIF(SQL!$E$5:$E$60,"Not Started")+COUNTIF(SQL!$E$5:$E$60,"Revise Again") | F5: =IFERROR(C5/B5,0)
A6: Data Warehouse | B6: =COUNTA('Data Warehouse'!$B$5:$B$38) | C6: =COUNTIF('Data Warehouse'!$E$5:$E$38,"Completed") | D6: =COUNTIF('Data Warehouse'!$E$5:$E$38,"In Progress") | E6: =COUNTIF('Data Warehouse'!$E$5:$E$38,"Not Started")+COUNTIF('Data Warehouse'!$E$5:$E$38,"Revise Again") | F6: =IFERROR(C6/B6,0)
A7: PySpark | B7: =COUNTA(PySpark!$B$5:$B$44) | C7: =COUNTIF(PySpark!$E$5:$E$44,"Completed") | D7: =COUNTIF(PySpark!$E$5:$E$44,"In Progress") | E7: =COUNTIF(PySpark!$E$5:$E$44,"Not Started")+COUNTIF(PySpark!$E$5:$E$44,"Revise Again") | F7: =IFERROR(C7/B7,0)
A8: Databricks | B8: =COUNTA(Databricks!$B$5:$B$41) | C8: =COUNTIF(Databricks!$E$5:$E$41,"Completed") | D8: =COUNTIF(Databricks!$E$5:$E$41,"In Progress") | E8: =COUNTIF(Databricks!$E$5:$E$41,"Not Started")+COUNTIF(Databricks!$E$5:$E$41,"Revise Again") | F8: =IFERROR(C8/B8,0)
A9: Project | B9: =COUNTA(Project!$B$5:$B$36) | C9: =COUNTIF(Project!$E$5:$E$36,"Completed") | D9: =COUNTIF(Project!$E$5:$E$36,"In Progress") | E9: =COUNTIF(Project!$E$5:$E$36,"Not Started")+COUNTIF(Project!$E$5:$E$36,"Revise Again") | F9: =IFERROR(C9/B9,0)
A10: Interview Essentials | B10: =COUNTA('Interview Essentials'!$B$5:$B$26) | C10: =COUNTIF('Interview Essentials'!$E$5:$E$26,"Completed") | D10: =COUNTIF('Interview Essentials'!$E$5:$E$26,"In Progress") | E10: =COUNTIF('Interview Essentials'!$E$5:$E$26,"Not Started")+COUNTIF('Interview Essentials'!$E$5:$E$26,"Revise Again") | F10: =IFERROR(C10/B10,0)
A11: OVERALL | B11: =SUM(B5:B10) | C11: =SUM(C5:C10) | D11: =SUM(D5:D10) | E11: =SUM(E5:E10) | F11: =IFERROR(C11/B11,0)
A14: Daily SQL Practice Snapshot
A15: Total Practice Days Logged: | C15: ='Daily SQL Practice Log'!C67
A16: Total Queries Solved: | C16: ='Daily SQL Practice Log'!C68
A17: Days Target Met (5-10 queries): | C17: ='Daily SQL Practice Log'!C69
A20: How to use this tracker
A21: 1. Go to each topic tab (SQL, Data Warehouse, PySpark, Databricks, Project, Interview Essentials) and update the 'Status' dropdown as you learn each subtopic.
A22: 2. Use 'Priority' to flag High/Medium/Low so you know what to focus on next.
A23: 3. Fill 'Date Started', 'Date Completed', 'Notes / Key Learnings', and 'Resource / Link' as you go.
A24: 4. Log daily SQL practice (5-10 queries) in the 'Daily SQL Practice Log' tab — it auto-flags whether you hit the target.
A25: 5. This Dashboard auto-updates counts and % complete per module from the Status columns — no manual editing needed here (except cells with formulas may be viewed only).
A27: Bhushan Jain — Amdocs/US Cellular order+billing + Tata Communications NOC. Project tab + How_to_Answer + My_Story use YOUR resume metrics (~60% less manual recon, 50%+ SQL, 99.9%+ NOC, ~35% automation). 50 tables is an interview DESIGN pattern, not a CV number. Yellow = Azure-only / newer Databricks — define correctly, do not bluff prod.

Sheet My_Story
A1: Bhushan Jain — spoken project story (only numbers from your resume)
A2: Use this tab in interviews. Column B is what you say. Column C is what you must not invent.
A4: Block | B4: Say this | C4: Do not say
A5: Who you are | B5: Bhushan Jain, Pune. About five years in telecom data/ops. Current: Amdocs, client US Cellular, Jun 2022–present. Previous: Tata Communications NOC, Jun 2020–May 2022. SQL and Python are strongest. | C5: Do not say 5.9 years Azure DE at TCL overlapping Amdocs. Do not quote 9 LPA unless you want that on the table.
A6: Current project | B6: US Cellular order management. Oracle holds orders/billing. I built Python + PL/SQL jobs on Linux cron: find stuck/failed orders, reconcile upstream vs downstream, bulk-fix status, HTML email of exceptions. Flask/FastAPI for JSON/XML sync. Dynatrace + BMC Remedy for prod. | C6: Do not claim you own the whole Azure subscription, Snowflake, or a life-sciences lake.
A7: Azure mapping (when they ask DE) | B7: Same pipeline in Azure words: Oracle --SHIR/ADF Copy--> ADLS Bronze --Databricks MERGE--> Silver recon --Gold star FactOrderEvent--> Power BI/ops. I speak ADF as the orchestrator equivalent of cron+config, not as a tool I used all day unless the JD is Azure-only and you have practiced the UI. | C7: Do not say you ran Photon, DLT, Unity Catalog, or 50 ADF pipelines in prod.
A8: Metrics you may use | B8: ~60% less manual order recon. 50%+ faster critical Oracle SQL (index + plan). Tata: 99.9%+ availability, 10+ Python/shell automations, ~35% productivity. Awards: Employee of the Month, USCC Client Appreciation. | C8: Do not invent TB/day, 50 tables, 3-hour-to-50-minute lake SLA, or row counts you never measured.
A9: 50 tables question | B9: Design answer: one parameterized pipeline + control table (load_type full vs incremental, watermark column, source, target). 10 small dims full daily, 40 facts incremental. Onboard = INSERT config. If they ask MY count: I will not guess; we grouped order-related entities the same way. | C9: Never: I ingested 50 USCC tables.
A10: Copy failed at 70% | B10: Job died mid-batch. Staging or MERGE by order_id so rerun is safe. Do not advance watermark. Retry transient. Quarantine poison rows. Send exception HTML. P1 with DBA. Reload from last watermark or that date slice. | C10: Do not describe an ADF monitor screen you have not used.
A11: STAR 1 — recon | B11: S: stuck orders missed SLA. T: cut manual queue. A: I wrote Python/pandas + PL/SQL bulk status + cron report. R: ~60% less manual recon, EOM/client award. | C11: Do not credit the whole OMS rewrite to yourself.
A12: STAR 2 — SQL | B12: S: critical recon query too slow for the batch window. T: cut runtime. A: I read the plan, added supporting index, rewrote non-sargable predicates. R: 50%+ faster. | C12: Do not say Spark AQE if it was Oracle.
A13: STAR 3 — Tata | B13: S: repetitive NOC checks. T: reduce toil. A: I automated 10+ log/disk/threshold jobs in Python/shell. R: ~35% productivity, 99.9%+ availability with the team. | C13: Do not rebrand Tata as TCL Azure Databricks.
A14: What you owned vs team | B14: I owned recon jobs, SQL tuning, exception reports, API glue, incident RCA. Platform/DBA owned Oracle HA. BI owned dashboards if they exist. Be explicit. | C14: Do not say I architected the medallion lakehouse for USCC.

Sheet How_to_Answer
A1: How to answer every tracker topic — 5 years Data Engineer (Azure / ADF / Databricks / SQL)
A2: Bhushan Jain | Amdocs–US Cellular (Jun 2022–present) | Tata Communications (Jun 2020–May 2022). Speak Oracle+Python+cron first; map to ADF/ADLS/Databricks when they ask Azure. Never quote 50 tables as your inventory.
A4: Theme | B4: They ask | C4: What you say (5 YOE) | D4: Delivery tip
A5: Intro (60–90s) | B5: Tell me about yourself | C5: Bhushan Jain, ~5 years, Pune. Amdocs (Jun 2022–present) on US Cellular telecom order management: Python + Oracle SQL/PL-SQL + Linux cron ETL, Flask/FastAPI integrations, production support. Earlier Tata Communications (Jun 2020–May 2022) NOC/Unix, 99.9%+ availability, 10+ Python/shell automations (~35% productivity). Strongest: SQL + Python. Azure DE wording: I ingest/reconcile order+billing data and would land it ADF→ADLS→Databricks medallion. Lead metric: ~60% less manual recon and 50%+ faster critical SQL. Stop. Do not list Snowflake/life-sciences/OBS from the ATS resume unless you can defend them. | D5: NOW → employer/client → stack you can defend → ONE metric → stop.
A6: Project story | B6: Walk through your architecture | C6: USCC OMS/billing on Oracle. Extract changed orders (watermark/status). Stage raw. Recon: PK, allowed status, upstream vs downstream. Bulk PL/SQL fixes. HTML exception report via cron/Sendmail. Monitor Dynatrace + Remedy. Azure mapping: Oracle--SHIR/ADF Copy-->ADLS Bronze-->Databricks Silver MERGE-->Gold FactOrderEvent star-->PBI/ops. You owned recon ETL and SQL tuning, not the whole cloud account. | D6: Draw boxes. Label what YOU built vs platform team.
A7: 50 tables ADF | B7: 40 incremental + 10 full daily | C7: This is a DESIGN question, not your resume count. Answer: one parameterized pipeline + control table (load_type, watermark_col, src, tgt, is_active). ForEach. Full = small dims; incremental = order/billing facts. Onboard = INSERT row. If they ask how many tables YOU had: 'I will not quote a number I cannot defend; the pattern is what I would use.' | D7: Never say you personally onboarded 50 USCC tables.
A8: Copy 70% failed | B8: How do you recover? | C8: Map to a mid-batch USCC job fail. Idempotent MERGE/staging; do not advance watermark; retry transient; quarantine poison; HTML exception list; P1 with DBA. Re-run from last watermark or delete that date slice then reload. Result: faster MTTR, Client Appreciation story. | D8: Use YOUR incident, not a fake ADF screenshot.
A9: PK vs Unique | B9: Difference? | C9: PK: one per table, no NULLs, identifies row, often clustered. UNIQUE: multiple allowed, one NULL in SQL Server unique index (historically), alternate keys. Both enforce uniqueness. | D9: Give an example: email UNIQUE, customer_id PK.
A10: RANK trio | B10: ROW_NUMBER vs RANK vs DENSE_RANK | C10: Same OVER clause. RN unique. RANK gaps after ties. DENSE no gaps. Dedup = RN=1. Top salary per dept = RN or DENSE depending if ties should share rank. | D10: Write OVER(PARTITION BY dept ORDER BY sal DESC) on a whiteboard.
A11: LEFT vs INNER | B11: Can LEFT be replaced by INNER? | C11: Only if you don't need unmatched left rows. WHERE on right table makes LEFT behave as INNER. Put right filters in ON to keep true LEFT. | D11: Draw two circles.
A12: CTE vs table vs view | B12: When each? | C12: CTE: readable query-scoped. Temp table: materialize + index. View: reusable saved SELECT, no data. Cannot always UPDATE CTE; yes if single base table. | D12: Mention recursive CTE separately.
A13: Incremental pipeline | B13: How do you load incrementally? | C13: Watermark column (modified_ts) in control table. Read last value → filter source → land Bronze → MERGE Silver → write new watermark. CDC if deletes required. Lookback window for late data. | D13: Mention failure = don't update watermark.
A14: Spark join tuning | B14: How do you optimize a slow join? | C14: Check sizes: broadcast small dim. Skew: AQE / salt / isolate hot key. Partition/ZORDER join keys. Avoid UDFs in join keys. Spark UI stragglers. Repartition by join key if both large. | D14: Always mention Spark UI evidence.
A15: Delta vs Parquet | B15: Why Delta? | C15: Parquet = files. Delta = Parquet + transaction log: ACID, MERGE, time travel, schema enforcement. Lakehouse table format. | D15: One sentence then table.
... A20: Behavioral | B20: Tell me about a failure or win | C20: Pick one STAR only: (1) stuck-order recon → Python/PL-SQL + reports → ~60% less manual. (2) slow critical SQL → index/plan → 50%+. (3) P1 with DBA → Client Appreciation. (4) Tata NOC automations → ~35% / 99.9%+. Learning: idempotent rerun, don't move watermark on fail. | D20: 90 seconds out loud. I not we.
A22: UNIVERSAL ANSWER FORMULA (use on any topic in SQL / DWH / PySpark / Databricks / Project tabs)
A23: 1) NAME IT: 'X is …' (precise definition). 2) PLACE IT: 'In my pipeline it sits in Bronze/Silver/Gold / ADF activity / Spark stage …'. 3) DO IT: one concrete mechanism (watermark column, MERGE ON bk, broadcast hint, ZORDER col). 4) COST/RISK: shuffle, small files, NOT IN + NULL, LEFT+WHERE becomes INNER, vacuum vs time travel. 5) PROOF: Spark UI / row counts / SLA minutes / onboarding a table via config. 6) If you are weak on a row marked In Progress: say 'I have used the adjacent pattern in prod; this exact feature I am hands-on this week' — then still give a correct definition. Never bluff Photon/DLT internals.

Sheet SQL
A1: SQL
A2: Basics -> Window Functions -> Aggregations -> Joins -> Query Optimization -> SCD -> CDC -> EXISTS -> MERGE
B3: HakerRank | C3: CodeChef
A4: # | B4: Topic Area | C4: Subtopic / Concept | D4: Priority | E4: Status | F4: Date Started | G4: Date Completed | H4: Notes / Key Learnings | I4: Resource / Link
A5: Basics
A6: 1 | B6: Basics | C6: SELECT, WHERE, ORDER BY, DISTINCT, LIMIT/TOP | D6: High | E6: Completed | F6: 44256 | G6: 44348 | H6: SAY: Filter in WHERE, sort last. DISTINCT is expensive (sort/hash). Prefer TOP/LIMIT after a precise WHERE. Interview trap: WHERE vs HAVING — WHERE before grouping, HAVING after. | I6: https://learn.microsoft.com/sql/t-sql/queries/select-transact-sql
A7: 2 | B7: Basics | C7: Filtering: IN, BETWEEN, LIKE, IS NULL | D7: High | E7: Completed | F7: 44256 | G7: 44348 | H7: SAY: IS NULL never equals NULL. LIKE '%x' cannot use a normal index. IN vs EXISTS: EXISTS often better for correlated existence checks. BETWEEN is inclusive. | I7: https://learn.microsoft.com/sql/t-sql/queries/predicates
A8: 3 | B8: Basics | C8: GROUP BY and HAVING | D8: High | E8: Completed | F8: 44256 | G8: 44378 | H8: SAY: SELECT non-aggregates must be in GROUP BY. HAVING filters groups (e.g. HAVING COUNT(*)>1). Interview: find duplicates = GROUP BY key HAVING COUNT(*)>1. | I8: https://learn.microsoft.com/sql/t-sql/queries/select-group-by-transact-sql
A9: 4 | B9: Basics | C9: Data types, constraints, basic DDL/DML | D9: High | E9: Completed | F9: 44256 | G9: 44409 | H9: SAY: PK/UNIQUE/NOT NULL/CHECK/FK. DDL=structure (CREATE/ALTER), DML=data (INSERT/UPDATE/DELETE/MERGE). Pick VARCHAR vs NVARCHAR, DATETIME2 vs DATETIME. | I9: https://learn.microsoft.com/sql/t-sql/statements/statements
A10: Aggregations
A11: 5 | B11: Aggregations | C11: COUNT, SUM, AVG, MIN, MAX | D11: High | E11: Completed | F11: 44256 | G11: 44348 | H11: SAY: COUNT(*) counts rows; COUNT(col) ignores NULLs. AVG ignores NULLs. Wrap with COALESCE if business wants zeros. | I11: https://learn.microsoft.com/sql/t-sql/functions/aggregate-functions-transact-sql
A12: 6 | B12: Aggregations | C12: GROUP BY with multiple columns | D12: High | E12: Completed | F12: 44287 | G12: 44409 | H12: SAY: Grain of the result = all GROUP BY columns. Example: sales by region AND product. If you add a column to SELECT, add it to GROUP BY or aggregate it. | I12: https://learn.microsoft.com/sql/t-sql/queries/select-group-by-transact-sql
A13: 7 | B13: Aggregations | C13: ROLLUP, CUBE, GROUPING SETS | D13: Medium | E13: In Progress | F13: 45306 | H13: SAY: ROLLUP = hierarchy totals (region→country→grand). CUBE = all combinations. GROUPING SETS = exact totals you want (cheaper than CUBE). GROUPING() flags super-aggregate NULL vs real NULL. | I13: https://learn.microsoft.com/sql/t-sql/queries/select-group-by-transact-sql
A14: Joins
A15: 8 | B15: Joins | C15: INNER JOIN | D15: High | E15: Completed | F15: 44256 | G15: 44348 | H15: SAY: Only matching keys. Use when both sides must exist (order + paying customer). Watch fan-out: join to a 1:M dim without grain control duplicates facts. | I15: https://learn.microsoft.com/sql/t-sql/queries/from-transact-sql
A16: 9 | B16: Joins | C16: LEFT / RIGHT JOIN | D16: High | E16: Completed | F16: 44256 | G16: 44378 | H16: SAY: LEFT keeps all left rows; unmatched right cols NULL. Filter on right table in WHERE turns it into INNER — put those predicates in ON. RIGHT is just flipped LEFT; I almost always write LEFT. | I16: https://learn.microsoft.com/sql/t-sql/queries/from-transact-sql
A17: 10 | B17: Joins | C17: FULL OUTER JOIN | D17: Medium | E17: Completed | F17: 44409 | G17: 44621 | H17: SAY: Keep unmatched from both sides. Use for reconciliation (source vs target row counts/keys). Rare in star-schema queries. | I17: https://learn.microsoft.com/sql/t-sql/queries/from-transact-sql
A18: 11 | B18: Joins | C18: SELF JOIN | D18: High | E18: Completed | F18: 44409 | G18: 44621 | H18: SAY: Table joined to itself with aliases. Classic: employee→manager (e.manager_id = m.emp_id), consecutive days, compare row to previous version. Need aliases or the query is invalid. | I18: https://learn.microsoft.com/sql/t-sql/queries/from-transact-sql
A19: 12 | B19: Joins | C19: CROSS JOIN | D19: Medium | E19: Completed | F19: 44409 | G19: 44621 | H19: SAY: Cartesian product. Use for generating calendars, all product×region combinations, or numbers tables. Accidental CROSS JOIN is a common explosion bug. | I19: https://learn.microsoft.com/sql/t-sql/queries/from-transact-sql
A20: 13 | B20: Joins | C20: Anti-join / Semi-join patterns (NOT EXISTS, NOT IN) | D20: High | E20: Completed | F20: 44562 | G20: 45078 | H20: SAY: Semi-join = EXISTS (rows that have a match). Anti-join = NOT EXISTS (no match). Prefer NOT EXISTS over NOT IN because NOT IN fails if the subquery has NULL. Interview favorite. | I20: https://learn.microsoft.com/sql/t-sql/language-elements/exists-transact-sql
A21: Window Functions
A22: 14 | B22: Window Functions | C22: ROW_NUMBER, RANK, DENSE_RANK | D22: High | E22: Completed | F22: 44562 | G22: 44927 | H22: SAY: All need OVER(PARTITION BY … ORDER BY …). ROW_NUMBER unique 1,2,3… RANK skips after ties (1,1,3). DENSE_RANK no gaps (1,1,2). Dedup: ROW_NUMBER()=1. Top-N per group: ROW_NUMBER<=N. | I22: https://learn.microsoft.com/sql/t-sql/functions/ranking-functions-transact-sql
A23: 15 | B23: Window Functions | C23: LEAD, LAG | D23: High | E23: Completed | F23: 44713 | G23: 45078 | H23: SAY: LAG = previous row, LEAD = next, same partition/order. Use for YoY, sessionization, SCD change detection (current vs previous status). Default offset 1; can supply default for first/last row. | I23: https://learn.microsoft.com/sql/t-sql/functions/analytic-functions-transact-sql
A24: 16 | B24: Window Functions | C24: SUM/AVG OVER (PARTITION BY ... ORDER BY ...) | D24: High | E24: Completed | F24: 44713 | G24: 45078 | H24: SAY: Window aggregates without collapsing rows. Running total: SUM(amt) OVER (PARTITION BY cust ORDER BY dt ROWS UNBOUNDED PRECEDING). Default RANGE vs ROWS can surprise with ties — I specify ROWS. | I24: https://learn.microsoft.com/sql/t-sql/queries/select-over-clause-transact-sql
A25: 17 | B25: Window Functions | C25: Running totals & moving averages | D25: High | E25: Completed | F25: 44713 | G25: 45292 | H25: SAY: Moving avg 7 days: AVG(x) OVER (ORDER BY d ROWS BETWEEN 6 PRECEDING AND CURRENT ROW). In Spark same idea with window spec. Call out frame clause in interviews. | I25: https://learn.microsoft.com/sql/t-sql/queries/select-over-clause-transact-sql
A26: 18 | B26: Window Functions | C26: NTILE, FIRST_VALUE, LAST_VALUE | D26: Medium | E26: Completed | F26: 44927 | G26: 45444 | H26: SAY: NTILE(4) quartiles. FIRST_VALUE/LAST_VALUE need a frame; LAST_VALUE often needs ROWS BETWEEN UNBOUNDED PRECEDING AND UNBOUNDED FOLLOWING or it returns current row. | I26: https://learn.microsoft.com/sql/t-sql/functions/analytic-functions-transact-sql
A27: Query Optimization
A28: 19 | B28: Query Optimization | C28: Reading execution/query plans | D28: High | E28: Completed | F28: 44562 | G28: 45627 | H28: SAY: Look for Clustered Index Scan vs Seek, Key Lookup, Hash vs Nested Loops, Sort, high estimated vs actual rows. SSMS: Actual plan. Spark: EXPLAIN / Spark UI DAG. Cardinality mistakes cause bad joins. | I28: https://learn.microsoft.com/sql/relational-databases/performance/execution-plans
A29: 20 | B29: Query Optimization | C29: Index usage basics | D29: High | E29: Completed | F29: 44409 | G29: 45078 | H29: SAY: B-tree index = sorted pointer. Helps WHERE/JOIN/ORDER BY on leading columns. Hurts heavy writes. Covering index includes selected columns to avoid lookups. | I29: https://learn.microsoft.com/sql/relational-databases/indexes/clustered-and-nonclustered-indexes-described
A30: 21 | B30: Query Optimization | C30: Avoiding SELECT *, sargable predicates | D30: High | E30: Completed | F30: 44562 | G30: 45078 | H30: SAY: Sargable = predicate can use index. Bad: WHERE YEAR(dt)=2024, WHERE col LIKE '%x', WHERE CAST(col AS date)=… Good: WHERE dt>='2024-01-01' AND dt<'2025-01-01'. SELECT * blocks covering indexes and wastes I/O. | I30: https://learn.microsoft.com/sql/relational-databases/performance/query-hints-transact-sql
A31: 22 | B31: Query Optimization | C31: CTE vs subquery vs temp table performance | D31: High | E31: Completed | F31: 44713 | G31: 45444 | H31: SAY: CTE is named query; may be inlined (not always materialized). Subquery similar. Temp table (#t) materializes, can index, good for reuse/large intermediates. Table variable weak stats. I use CTE for readability; temp table when the optimizer misestimates. | I31: https://learn.microsoft.com/sql/t-sql/queries/with-common-table-expression-transact-sql
A32: SCD Types
A33: 23 | B33: SCD Types | C33: SCD Type 0, 1, 2, 3 concepts | D33: High | E33: Completed | F33: 44562 | G33: 45078 | H33: SAY: 0=retain original (audit). 1=overwrite (no history). 2=new row + effective dates/is_current (full history) — most used in DWH. 3=previous-value column (limited history). Type 6 = 1+2+3 hybrid. | I33: https://www.kimballgroup.com/data-warehouse-business-intelligence-resources/kimball-techniques/dimensional-modeling-techniques/type-2/
A34: 24 | B34: SCD Types | C34: Implementing SCD Type 2 with SQL | D34: High | E34: Completed | F34: 44713 | G34: 45292 | H34: SAY: MERGE source to target: 1) expire current row (is_current=0, end_date=today) when attributes change 2) insert new current row with new surrogate key. Hash of business attrs to detect change. Always mention surrogate key. | I34: https://learn.microsoft.com/sql/t-sql/statements/merge-transact-sql
A35: CDC
A36: 25 | B36: CDC | C36: Change Data Capture concepts | D36: High | E36: Completed | F36: 44713 | G36: 45444 | H36: SAY: Capture inserts/updates/deletes from source instead of full dump. Enables incremental + deletes. Sources: SQL CDC, Oracle GoldenGate, Debezium, ADF watermark, Databricks Auto Loader. Need a reliable change identifier. | I36: https://learn.microsoft.com/sql/relational-databases/track-changes/about-change-data-capture-sql-server
A37: 26 | B37: CDC | C37: CDC implementation patterns (timestamp/log-based) | D37: High | E37: Completed | F37: 44927 | G37: 45809 | H37: SAY: Timestamp/watermark: WHERE updated_at > last_success (misses deletes unless soft-delete). Log-based CDC: read transaction log (true deletes, lower source load). I stored last watermark in a control table and advanced it only after successful load. | I37: https://learn.microsoft.com/azure/data-factory/tutorial-incremental-copy-overview
A38: EXISTS
A39: 27 | B39: EXISTS | C39: EXISTS vs IN vs JOIN performance | D39: High | E39: Completed | F39: 44562 | G39: 45292 | H39: SAY: EXISTS short-circuits on first match (semi-join). IN builds a set; NULL in list breaks NOT IN. JOIN can duplicate if 1:M. For 'does a child exist?' I use EXISTS. Confirm with actual plan. | I39: https://learn.microsoft.com/sql/t-sql/language-elements/exists-transact-sql
A40: MERGE
...

Sheet Data Warehouse
A1: Data Warehouse
A2: Fact/Dim, Star & Snowflake Schema, Keys, OLAP vs OLTP, ETL/ELT concepts
B3: BigQuery | C3: Snowflake | D3: Azure - Synapse
A4: # | B4: Topic Area | C4: Subtopic / Concept | D4: Priority | E4: Status | F4: Date Started | G4: Date Completed | H4: Notes / Key Learnings | I4: Resource / Link
A5: Fact & Dimension Tables
A6: 1 | B6: Fact & Dimension Tables | C6: Fact table concepts (grain, measures) | D6: High | E6: Completed | F6: 44440 | G6: 44713 | H6: SAY: Grain first — one row = one business event (e.g. one order line). Measures: additive (amount), semi-additive (balance), non-additive (ratio). Never mix grains in one fact. | I6: https://www.kimballgroup.com/data-warehouse-business-intelligence-resources/kimball-techniques/dimensional-modeling-techniques/fact-table/
A7: 2 | B7: Fact & Dimension Tables | C7: Dimension table concepts (attributes, hierarchies) | D7: High | E7: Completed | F7: 44440 | G7: 44713 | H7: SAY: Dims describe the who/what/where/when. Hierarchies: Product→Category→Dept, Date→Month→Year. Wide, denormalized in star. Surrogate integer keys join to facts. | I7: https://www.kimballgroup.com/data-warehouse-business-intelligence-resources/kimball-techniques/dimensional-modeling-techniques/dimension-table-structure/
A8: 3 | B8: Fact & Dimension Tables | C8: Types of fact tables (transactional, snapshot, accumulating) | D8: High | E8: Completed | F8: 44562 | G8: 45078 | H8: SAY: Transaction = one row per event. Periodic snapshot = inventory/balance each day. Accumulating snapshot = process pipeline (order→ship→deliver) with multiple date keys and milestones. | I8: https://www.kimballgroup.com/data-warehouse-business-intelligence-resources/kimball-techniques/dimensional-modeling-techniques/transaction-fact-table/
A9: Schema Design
A10: 4 | B10: Schema Design | C10: Star Schema | D10: High | E10: Completed | F10: 44440 | G10: 44713 | H10: SAY: Central fact + denormalized dims. Simple joins, BI-friendly, my default for Gold. Draw: FactSales in center, DimDate/Customer/Product/Store around it. | I10: https://learn.microsoft.com/power-bi/guidance/star-schema
A11: 5 | B11: Schema Design | C11: Snowflake Schema | D11: Medium | E11: Completed | F11: 44562 | G11: 44927 | H11: SAY: Dims normalized into sub-dims (Product→Category table). Saves space, more joins. I snowflake only when a dim is huge or shared in a strict 3NF warehouse. | I11: https://learn.microsoft.com/power-bi/guidance/star-schema
A12: 6 | B12: Schema Design | C12: Star vs Snowflake trade-offs | D12: High | E12: Completed | F12: 44562 | G12: 45078 | H12: SAY: Star = faster queries, simpler Power BI. Snowflake = less duplication, more joins, harder for BI. Interview: Power BI prefers star. | I12: https://learn.microsoft.com/power-bi/guidance/star-schema
A13: Keys
A14: 7 | B14: Keys | C14: Primary Key | D14: High | E14: Completed | F14: 44256 | G14: 44409 | H14: SAY: Uniquely identifies a row; implies NOT NULL + UNIQUE; in SQL Server usually clustered. One PK per table. In lakehouse, PK may be declared in Unity Catalog but not always physically enforced like RDBMS. | I14: https://learn.microsoft.com/sql/relational-databases/tables/primary-and-foreign-key-constraints
A15: 8 | B15: Keys | C15: Foreign Key | D15: High | E15: Completed | F15: 44256 | G15: 44409 | H15: SAY: Child column references parent PK/UNIQUE. Enforces referential integrity. In warehouse ETL we often enforce in pipeline (orphan checks) rather than heavy FKs on large facts. | I15: https://learn.microsoft.com/sql/relational-databases/tables/primary-and-foreign-key-constraints
A16: 9 | B16: Keys | C16: Surrogate Key vs Natural Key | D16: High | E16: Completed | F16: 44440 | G16: 44896 | H16: SAY: Natural = business key (email, product SKU) — can change, composite, wide. Surrogate = warehouse-generated integer/hash — stable for SCD2 (new version = new SK). Facts store surrogate keys. | I16: https://www.kimballgroup.com/data-warehouse-business-intelligence-resources/kimball-techniques/dimensional-modeling-techniques/surrogate-keys/
A17: 10 | B17: Keys | C17: Composite Key | D17: Medium | E17: Completed | F17: 44348 | G17: 44713 | H17: SAY: PK of 2+ columns (order_id+line_no). Fine in OLTP. In DWH I still add a surrogate for facts/dims to keep joins skinny. | I17: https://learn.microsoft.com/sql/relational-databases/tables/primary-and-foreign-key-constraints
A18: OLAP vs OLTP
A19: 11 | B19: OLAP vs OLTP | C19: OLTP characteristics | D19: High | E19: Completed | F19: 44256 | G19: 44562 | H19: SAY: Many small read/write tx, normalized, current state, app-facing (orders, CRM). Latency in ms. Azure SQL / on-prem SQL Server. | I19: https://learn.microsoft.com/azure/architecture/data-guide/relational-data/online-transaction-processing
A20: 12 | B20: OLAP vs OLTP | C20: OLAP characteristics | D20: High | E20: Completed | F20: 44440 | G20: 44713 | H20: SAY: Analytical, large scans, historical, denormalized/star, aggregations. Synapse, Fabric Warehouse, Databricks SQL, Power BI. Latency seconds to minutes. | I20: https://learn.microsoft.com/azure/architecture/data-guide/relational-data/online-analytical-processing
A21: 13 | B21: OLAP vs OLTP | C21: Use case differences | D21: High | E21: Completed | F21: 44440 | G21: 44713 | H21: SAY: Checkout system = OLTP. Monthly sales dashboard / what-if = OLAP. Don't run heavy reports on OLTP; replicate/CDC to the warehouse. | I21: https://learn.microsoft.com/azure/architecture/data-guide/relational-data/online-analytical-processing
A22: ETL Concepts
A23: 14 | B23: ETL Concepts | C23: ETL vs ELT | D23: High | E23: Completed | F23: 44440 | G23: 44927 | H23: SAY: ETL transform in engine then load (SSIS/ADF mapping). ELT land raw then transform in lake/warehouse (ADF copy → Databricks/Synapse). Cloud default is ELT + medallion. | I23: https://learn.microsoft.com/azure/architecture/data-guide/relational-data/etl
A24: 15 | B24: ETL Concepts | C24: Full Load | D24: High | E24: Completed | F24: 44348 | G24: 44713 | H24: SAY: Truncate+reload or overwrite folder. Simple, handles deletes, expensive. Use for small dims or first load. Staging then swap for atomicity. | I24: https://learn.microsoft.com/azure/data-factory/tutorial-incremental-copy-overview
A25: 16 | B25: ETL Concepts | C25: Incremental Load | D25: High | E25: Completed | F25: 44562 | G25: 45078 | H25: SAY: Load only new/changed rows via watermark, CDC, or hash compare. Faster, cheaper. Must define delete strategy (soft-delete flag or CDC). | I25: https://learn.microsoft.com/azure/data-factory/tutorial-incremental-copy-overview
A26: 17 | B26: ETL Concepts | C26: Batch Processing mode | D26: High | E26: Completed | F26: 44348 | G26: 44927 | H26: SAY: Bounded data on a schedule (hourly/daily ADF trigger + Databricks job). High throughput, simpler exactly-once. SLA = batch window. | I26: https://learn.microsoft.com/azure/architecture/data-guide/big-data/batch-processing
A27: 18 | B27: ETL Concepts | C27: Streaming mode | D27: High | E27: Completed | F27: 44927 | G27: 45809 | H27: SAY: Unbounded events (Event Hub/Kafka → Structured Streaming / Auto Loader). Watermarks for late data. Micro-batch is the usual Spark mode. I used it for near-real-time Bronze. | I27: https://learn.microsoft.com/azure/architecture/data-guide/big-data/real-time-processing
A28: Modeling Approaches
A29: 19 | B29: Modeling Approaches | C29: Kimball (bottom-up) vs Inmon (top-down) | D29: Medium | E29: Completed | F29: 44713 | G29: 45292 | H29: SAY: Kimball: dimensional marts first, conformed dims, faster delivery — what I use. Inmon: normalized enterprise EDW first, then marts — heavier governance. Hybrid is common. | I29: https://www.kimballgroup.com/data-warehouse-business-intelligence-resources/kimball-techniques/dimensional-modeling-techniques/
A30: 20 | B30: Modeling Approaches | C30: Conceptual, Logical, Physical data models | D30: Medium | E30: Completed | F30: 44562 | G30: 45078 | H30: SAY: Conceptual=business entities. Logical=keys/attributes/relationships, platform-agnostic. Physical=tables, partitions, file format, indexes. Interviews: I start logical grain then physical Delta partition strategy. | I30: https://learn.microsoft.com/power-bi/guidance/star-schema
A31: 21 | B31: Modeling Approaches | C31: Data Mart vs Data Warehouse | D31: High | E31: Completed | F31: 44440 | G31: 44896 | H31: SAY: Warehouse = enterprise, many subjects. Mart = department slice (Finance/Sales) often star. Gold layer marts feed Power BI. | I31: https://learn.microsoft.com/azure/architecture/data-guide/relational-data/data-warehousing
A32: Advanced Dimension Concepts
A33: 22 | B33: Advanced Dimension Concepts | C33: Conformed Dimension | D33: High | E33: Completed | F33: 44713 | G33: 45292 | H33: SAY: Same dim reused across facts/marts (DimDate, DimCustomer) so reports can drill across processes. Mastered once in Silver/Gold. | I33: https://www.kimballgroup.com/data-warehouse-business-intelligence-resources/kimball-techniques/dimensional-modeling-techniques/conformed-dimension/
A34: 23 | B34: Advanced Dimension Concepts | C34: Junk Dimension | D34: Medium | E34: Completed | F34: 44927 | G34: 45444 | H34: SAY: Pack low-cardinality flags/codes (yes/no, status) into one dim to avoid dozens of tiny dims. Degenerate is different (see next). | I34: https://www.kimballgroup.com/data-warehouse-business-intelligence-resources/kimball-techniques/dimensional-modeling-techniques/junk-dimension/
A35: 24 | B35: Advanced Dimension Concepts | C35: Degenerate Dimension | D35: Medium | E35: Completed | F35: 44927 | G35: 45444 | H35: SAY: A dimension attribute stored on the fact because it has no other attributes — e.g. invoice_number, ticket_id. No separate dim table. | I35: https://www.kimballgroup.com/data-warehouse-business-intelligence-resources/kimball-techniques/dimensional-modeling-techniques/degenerate-dimension/
A36: 25 | B36: Advanced Dimension Concepts | C36: Slowly Changing Dimension Type 3, 4, 6 (hybrid) | D36: Medium | E36: In Progress | F36: 45292 | H36: SAY: T3=current + previous column. T4=history mini-table (mini-dimension). T6=1+2+3 (current overwrite + history rows + previous). I implement T2 in production; mention T6 if they ask hybrids. | I36: https://www.kimballgroup.com/data-warehouse-business-intelligence-resources/kimball-techniques/dimensional-modeling-techniques/type-6/
A37: Advanced Fact Concepts
A38: 26 | B38: Advanced Fact Concepts | C38: Factless Fact Table | D38: Medium | E38: Completed | F38: 44927 | G38: 45444 | H38: SAY: No numeric measure — just events or coverage (student attended class, promo was in effect). COUNT(*) is the measure. Used for many-to-many coverage. | I38: https://www.kimballgroup.com/data-warehouse-business-intelligence-resources/kimball-techniques/dimensional-modeling-techniques/factless-fact-table/
A40: EXAMPLE (for reference only — edit/delete before use): Topic Area: Schema Design | Subtopic: Star Schema | Priority: High | Status: Completed | Notes: Understood denormalized dims joined directly to fact table; drew sample schema for retail sales.

Sheet PySpark
A1: PySpark
A2: In-depth architecture, DataFrame fundamentals, joins, and performance tuning
A4: # | B4: Topic Area | C4: Subtopic / Concept | D4: Priority | E4: Status | F4: Date Started | G4: Date Completed | H4: Notes / Key Learnings | I4: Resource / Link
A5: Architecture
A6: 1 | B6: Architecture | C6: Driver, Executor, Cluster Manager overview | D6: High | E6: Completed | F6: 44562 | G6: 45078 | H6: SAY: Driver builds DAG and schedules. Executors run tasks and cache data. Cluster manager (YARN/K8s/Databricks) grants CPUs/RAM. If driver OOMs, you collected too much to driver. | I6: https://spark.apache.org/docs/latest/cluster-overview.html
A7: 2 | B7: Architecture | C7: How an application runs in the backend (submission to execution) | D7: High | E7: Completed | F7: 44713 | G7: 45292 | H7: SAY: Submit job → cluster starts → SparkSession → lazy transformations build DAG → action triggers jobs. Databricks job cluster: VM provision → Spark start → notebook → teardown. | I7: https://spark.apache.org/docs/latest/job-scheduling.html
A8: 3 | B8: Architecture | C8: Job -> Stages -> Tasks breakdown | D8: High | E8: Completed | F8: 44713 | G8: 45292 | H8: SAY: Action = Job. Shuffle boundary = new Stage. Task = one partition on one core. 200 shuffle partitions default — tune spark.sql.shuffle.partitions / AQE. | I8: https://spark.apache.org/docs/latest/cluster-overview.html
A9: 4 | B9: Architecture | C9: Lazy Evaluation & DAG | D9: High | E9: Completed | F9: 44562 | G9: 44927 | H9: SAY: Transformations don't run until an action (write, count, show). DAG is lineage so Spark can recompute lost partitions. Explain() shows the plan before you pay for a job. | I9: https://spark.apache.org/docs/latest/rdd-programming-guide.html#rdd-operations
A10: File Formats
A11: 5 | B11: File Formats | C11: CSV | D11: High | E11: Completed | F11: 44348 | G11: 44562 | H11: SAY: Row text, no types, no pushdown. Landing only. InferSchema scans twice. I set header, delimiter, quote, mode=PERMISSIVE/FAILFAST. | I11: https://spark.apache.org/docs/latest/sql-data-sources-csv.html
A12: 6 | B12: File Formats | C12: Parquet | D12: High | E12: Completed | F12: 44562 | G12: 44927 | H12: SAY: Columnar, compressed, predicate/column pushdown. Default analytics format. Delta = Parquet + _delta_log. Partition on low-cardinality columns used in filters. | I12: https://spark.apache.org/docs/latest/sql-data-sources-parquet.html
A13: 7 | B13: File Formats | C13: AVRO | D13: Medium | E13: Completed | F13: 44927 | G13: 45444 | H13: SAY: Row-based, strong schema, good for Kafka CDC. Heavier for analytics than Parquet. I convert Avro/JSON Bronze → Parquet/Delta Silver. | I13: https://spark.apache.org/docs/latest/sql-data-sources-avro.html
A14: DataFrame Fundamentals
A15: 8 | B15: DataFrame Fundamentals | C15: Creating & transforming DataFrames | D15: High | E15: Completed | F15: 44562 | G15: 44927 | H15: SAY: spark.read / createDataFrame / spark.sql. Immutable: each transform returns a new DF. Prefer built-in functions over UDFs. | I15: https://spark.apache.org/docs/latest/sql-getting-started.html
A16: 9 | B16: DataFrame Fundamentals | C16: Common transformations (select, filter, withColumn, groupBy) | D16: High | E16: Completed | F16: 44562 | G16: 44927 | H16: SAY: Narrow: select/filter/withColumn. Wide: groupBy/join/distinct. Chain transforms; one action at the end. withColumn in a loop is an anti-pattern — use select with expressions. | I16: https://spark.apache.org/docs/latest/api/python/reference/pyspark.sql/dataframe.html
A17: 10 | B17: DataFrame Fundamentals | C17: Actions vs Transformations | D17: High | E17: Completed | F17: 44562 | G17: 44927 | H17: SAY: Transform=lazy (map/filter/select). Action=eager (count, collect, write, show). Multiple actions recompute unless cache. collect() on big data kills the driver. | I17: https://spark.apache.org/docs/latest/rdd-programming-guide.html#rdd-operations
A18: Joins
A19: 11 | B19: Joins | C19: Broadcast Hash Join | D19: High | E19: Completed | F19: 44927 | G19: 45444 | H19: SAY: Small side (dim) copied to every executor; no shuffle of the big fact. Hint: broadcast(df). Threshold spark.sql.autoBroadcastJoinThreshold (~10MB default, raise carefully). Best 5-YOE join answer. | I19: https://spark.apache.org/docs/latest/sql-performance-tuning.html#broadcast-hash-join
A20: 12 | B20: Joins | C20: Sort Merge Join | D20: High | E20: Completed | F20: 44927 | G20: 45444 | H20: SAY: Default for two large tables: shuffle + sort both by key, merge. Needs even keys. Skew on one key blows one task. AQE can split skewed partitions. | I20: https://spark.apache.org/docs/latest/sql-performance-tuning.html
A21: 13 | B21: Joins | C21: Shuffle Hash Join | D21: Medium | E21: In Progress | F21: 45444 | H21: SAY: Shuffle both sides, hash-join per partition (no full sort). Used when tables aren't huge enough for SMJ but too big to broadcast. Less common to tune manually; know it exists vs BHJ/SMJ. | I21: https://www.databricks.com/blog/2020/12/05/faster-sql-adaptive-query-execution-in-databricks.html
A22: Performance Tuning
A23: 14 | B23: Performance Tuning | C23: Partitioning | D23: High | E23: Completed | F23: 44713 | G23: 45292 | H23: SAY: Spark partitions = parallelism. Table partitions = directory layout (date=). Too many small partitions = small-file problem. Partition by ingestion_date or high-filter columns with sane cardinality. | I23: https://spark.apache.org/docs/latest/sql-data-sources-load-save-functions.html#partition-discovery
A24: 15 | B24: Performance Tuning | C24: Repartition vs Coalesce | D24: High | E24: Completed | F24: 44927 | G24: 45444 | H24: SAY: repartition(n) full shuffle, can increase or decrease, good before writes. coalesce(n) only shrinks, no full shuffle, may leave skew. Before write I often repartition to target file count. | I24: https://spark.apache.org/docs/latest/api/python/reference/pyspark.sql/api/pyspark.sql.DataFrame.repartition.html
A25: 16 | B25: Performance Tuning | C25: Shuffle operations | D25: High | E25: Completed | F25: 44713 | G25: 45292 | H25: SAY: Network exchange across executors (join/groupBy/repartition). Dominant cost. Reduce shuffles, increase parallelism, fix skew, enable AQE. Spark UI: Shuffle Read/Write bytes. | I25: https://spark.apache.org/docs/latest/rdd-programming-guide.html#shuffle-operations
A26: 17 | B26: Performance Tuning | C26: Cardinality | D26: High | E26: Completed | F26: 44927 | G26: 45444 | H26: SAY: Distinct count of a key. High cardinality partition columns = millions of folders (bad). Low cardinality join key can skew. Estimate with approx_count_distinct. | I26: https://spark.apache.org/docs/latest/sql-ref-functions-builtin.html
A27: 18 | B27: Performance Tuning | C27: Data Skew & handling techniques (salting) | D27: High | E27: Completed | F27: 45078 | G27: 45809 | H27: SAY: One key (NULL, 'Unknown', popular customer) owns most data → one slow task. Fixes: AQE skew join, filter nulls, salt key (key+random) then aggregate, two-phase aggregate, isolate hot keys. | I27: https://docs.databricks.com/en/optimizations/aqe.html
A28: 19 | B28: Performance Tuning | C28: Broadcast variables/joins | D28: High | E28: Completed | F28: 44927 | G28: 45444 | H28: SAY: Broadcast join = DF hint. Broadcast variable = read-only lookup (dict) shipped once to executors for UDFs/maps. Don't broadcast a huge DF (driver/executor OOM). | I28: https://spark.apache.org/docs/latest/rdd-programming-guide.html#broadcast-variables
A29: 20 | B29: Performance Tuning | C29: Predicate Pushdown | D29: High | E29: Completed | F29: 44927 | G29: 45444 | H29: SAY: Filter applied at Parquet/Delta scan so we read fewer row groups. Needs filter on physical columns, not wrapped in UDF. Partition pruning is the folder-level version. | I29: https://spark.apache.org/docs/latest/sql-data-sources-parquet.html
A30: 21 | B30: Performance Tuning | C30: Caching vs Persistence (storage levels) | D30: Medium | E30: Completed | F30: 45078 | G30: 45658 | H30: SAY: cache() = MEMORY_AND_DISK. persist(MEMORY_ONLY) faster but can OOM. Use only if reused across actions. unpersist() after. Delta tables usually cheaper to re-read than cache huge DFs. | I30: https://spark.apache.org/docs/latest/rdd-programming-guide.html#rdd-persistence
A31: 22 | B31: Performance Tuning | C31: Serialization (Kryo vs Java) | D31: Low | E31: In Progress | F31: 45444 | H31: SAY: Kryo is faster/smaller than Java serializer for RDDs. DataFrames already use Tungsten binary. Mention Kryo if they ask RDD tuning; not the first lever for DataFrame jobs. | I31: https://spark.apache.org/docs/latest/tuning.html#data-serialization
A32: 23 | B32: Performance Tuning | C32: Adaptive Query Execution (AQE) | D32: High | E32: Completed | F32: 45292 | G32: 45992 | H32: SAY: Spark 3+ re-plans at runtime: coalesces shuffle partitions, switches to broadcast if size small, handles skew. spark.sql.adaptive.enabled=true (default on Databricks). Check Spark UI for AQE events. | I32: https://spark.apache.org/docs/latest/sql-performance-tuning.html#adaptive-query-execution
A33: 24 | B33: Performance Tuning | C33: Small file problem & solutions | D33: High | E33: Completed | F33: 44927 | G33: 45809 | H33: SAY: Thousands of tiny Parquet files kill listing and jobs. Causes: over-partitioning, many parallel writers. Fixes: coalesce/repartition before write, Auto Loader + OPTIMIZE, target file size 128–1024MB, liquid clustering. | I33: https://docs.databricks.com/en/delta/best-practices.html
A34: Core Concepts
A35: 25 | B35: Core Concepts | C35: RDD vs DataFrame vs Dataset | D35: High | E35: Completed | F35: 44562 | G35: 45078 | H35: SAY: RDD=untyped partitions, no optimizer. DataFrame=Dataset[Row], Catalyst+Tungsten — what I use in PySpark. Dataset=typed JVM API, not in Python. Prefer DataFrame functions. | I35: https://spark.apache.org/docs/latest/sql-programming-guide.html
A36: 26 | B36: Core Concepts | C36: Spark SQL basics | D36: High | E36: Completed | F36: 44562 | G36: 45078 | H36: SAY: df.createOrReplaceTempView; spark.sql. Same engine as DataFrame API. Good for analysts; I mix both. Unity Catalog tables: spark.table('cat.schema.t'). | I36: https://spark.apache.org/docs/latest/sql-programming-guide.html
A37: 27 | B37: Core Concepts | C37: UDFs & Pandas UDFs (and their performance cost) | D37: High | E37: Completed | F37: 45078 | G37: 45809 | H37: SAY: Python UDF row-at-a-time, kills Catalyst, serialization cost. Pandas UDF (vectorized Arrow) better. Best: native Spark functions. I only UDF when no built-in exists. | I37: https://spark.apache.org/docs/latest/api/python/user_guide/sql/arrow_pandas.html
A38: 28 | B38: Core Concepts | C38: Cluster deployment modes (client vs cluster) | D38: Medium | E38: Completed | F38: 45078 | G38: 45658 | H38: SAY: Client: driver on submit machine (notebooks). Cluster: driver on a worker (production jobs). Databricks abstracts this; job cluster vs all-purpose is the practical distinction. | I38: https://spark.apache.org/docs/latest/cluster-overview.html
A39: 29 | B39: Core Concepts | C39: Memory management (execution vs storage memory, spill) | D39: Medium | E39: Completed | F39: 45292 | G39: 45992 | H39: SAY: Unified memory: execution (shuffles/joins) vs storage (cache). Spill to disk if RAM short — slow but not fail. OOM = raise worker memory, reduce partition size, avoid cache+shuffle together. | I39: https://spark.apache.org/docs/latest/tuning.html#memory-management-overview
A40: 30 | B40: Core Concepts | C40: Checkpointing | D40: Medium | E40: In Progress | F40: 45444 | H40: SAY: Truncate RDD lineage to reliable storage. Streaming: checkpoint location for offsets/state. Delta streaming needs a checkpoint path per stream. Don't share checkpoints across pipelines. | I40: https://spark.apache.org/docs/latest/structured-streaming-programming-guide.html#recovering-from-failures-with-checkpointing
A41: 31 | B41: Core Concepts | C41: Reading the Spark UI (DAG, stages, tasks, shuffle) | D41: High | E41: Completed | F41: 44927 | G41: 45809 | H41: SAY: Jobs→Stages: look for stragglers, GC, shuffle spill, input vs output. SQL tab for plans. One slow task = skew. Many tiny tasks = too many partitions. | I41: https://spark.apache.org/docs/latest/web-ui.html
...

Sheet Databricks
A1: Databricks
A2: Delta tables, compute, optimization techniques, Catalyst internals, Lakeflow, Medallion architecture
A4: # | B4: Topic Area | C4: Subtopic / Concept | D4: Priority | E4: Status | F4: Date Started | G4: Date Completed | H4: Notes / Key Learnings | I4: Resource / Link
A5: Delta Tables (Important)
A6: 1 | B6: Delta Tables (Important) | C6: Delta Lake fundamentals (transaction log, ACID) | D6: High | E6: Completed | F6: 44927 | G6: 45444 | H6: SAY: Open table format: Parquet data + _delta_log JSON/checkpoint. ACID, MERGE, time travel. Concurrent writers coordinated by log. This is the core of a Databricks lakehouse. | I6: https://docs.databricks.com/en/delta/index.html
A7: 2 | B7: Delta Tables (Important) | C7: Time Travel & versioning | D7: High | E7: Completed | F7: 45078 | G7: 45627 | H7: SAY: VERSION AS OF n or TIMESTAMP AS OF. DESCRIBE HISTORY. Rollback after bad MERGE. Retention tied to VACUUM (default 7 days). Don't vacuum if you need long time travel. | I7: https://docs.databricks.com/en/delta/history.html
A8: 3 | B8: Delta Tables (Important) | C8: Schema evolution & enforcement | D8: High | E8: Completed | F8: 45078 | G8: 45809 | H8: SAY: Enforcement rejects extra/wrong types by default. Evolution: mergeSchema / spark.databricks.delta.schema.autoMerge. Auto Loader schemaLocation tracks drift. I allow additive columns, fail on type widening unless planned. | I8: https://docs.databricks.com/en/delta/update-schema.html
A9: Compute & Notebooks
A10: 4 | B10: Compute & Notebooks | C10: Notebooks basics & widgets | D10: High | E10: Completed | F10: 44713 | G10: 45078 | H10: SAY: Cells SQL/Python/Scala. Widgets parameterize env, load_date. dbutils.widgets.get. Production: jobs pass parameters; notebooks stay thin, logic in repos. | I10: https://docs.databricks.com/en/notebooks/index.html
A11: 5 | B11: Compute & Notebooks | C11: Cluster types (All-purpose, Job, SQL Warehouse) | D11: High | E11: Completed | F11: 44713 | G11: 45292 | H11: SAY: All-purpose = interactive, always-on cost. Job cluster = dedicated per run, cheaper, isolated. SQL Warehouse = BI/JDBC. I develop on all-purpose, production on job clusters. | I11: https://docs.databricks.com/en/compute/index.html
A12: 6 | B12: Compute & Notebooks | C12: Cluster sizing & autoscaling | D12: High | E12: Completed | F12: 44927 | G12: 45809 | H12: SAY: Size for shuffle (more workers) vs memory (bigger workers). Min/max autoscaling. Spot for non-critical. Photon for SQL/Delta. Watch idle all-purpose clusters — biggest cost leak. | I12: https://docs.databricks.com/en/compute/cluster-config-best-practices.html
A13: Delta Optimization
A14: 7 | B14: Delta Optimization | C14: OPTIMIZE (compaction / Z-Ordering) | D14: High | E14: Completed | F14: 45078 | G14: 45809 | H14: SAY: OPTIMIZE compact small files. ZORDER BY (filter columns) co-locates data for data skipping. Don't Z-order 10 columns — 1–4 high-filter cols. Schedule after MERGE. | I14: https://docs.databricks.com/en/delta/optimize.html
A15: 8 | B15: Delta Optimization | C15: VACUUM | D15: High | E15: Completed | F15: 45078 | G15: 45809 | H15: SAY: Deletes unreferenced files older than retention (default 168h). Needed after OPTIMIZE/MERGE or storage grows. Time travel limited after vacuum. DRY RUN first. | I15: https://docs.databricks.com/en/delta/vacuum.html
A16: 9 | B16: Delta Optimization | C16: Liquid Clustering | D16: Medium | E16: In Progress | F16: 45809 | H16: SAY: Replaces static Hive-style partitions/ZORDER for many tables. CLUSTER BY keys; incremental clustering. Better when partition columns were guessed wrong. Mention as modern alternative in interviews. | I16: https://docs.databricks.com/en/delta/clustering.html
A17: 10 | B17: Delta Optimization | C17: Bucketing | D17: Low | E17: In Progress | F17: 45292 | H17: SAY: Hive buckets hash-pre-shuffle joins. Rarely my first tool on Databricks vs ZORDER/liquid/AQE. Know the term; don't oversell. | I17: https://spark.apache.org/docs/latest/sql-data-sources-load-save-functions.html#bucketing-sorting-and-partitioning
A18: 11 | B18: Delta Optimization | C18: Predictive Optimization | D18: Medium | E18: In Progress | F18: 45901 | H18: SAY: UC managed tables: Databricks automatically OPTIMIZE/VACUUM. I still know manual OPTIMIZE for non-managed or when I need a specific ZORDER. | I18: https://docs.databricks.com/en/optimizations/predictive-optimization.html
A19: Query Engine Internals
A20: 12 | B20: Query Engine Internals | C20: Catalyst Optimizer overview | D20: High | E20: Completed | F20: 45078 | G20: 45658 | H20: SAY: Rule-based + cost-based optimizer: analysis → logical optimization (predicate pushdown, column pruning) → physical planning → codegen. UDFs block many optimizations. | I20: https://www.databricks.com/glossary/catalyst-optimizer
A21: 13 | B21: Query Engine Internals | C21: Logical Plan | D21: Medium | E21: Completed | F21: 45078 | G21: 45658 | H21: SAY: What to do: parsed SQL/DF unresolved → analyzed (catalog types) → optimized logical. df.explain('extended') shows Parsed/Analyzed/Optimized Logical. | I21: https://spark.apache.org/docs/latest/sql-performance-tuning.html
A22: 14 | B22: Query Engine Internals | C22: Physical Plan | D22: Medium | E22: Completed | F22: 45078 | G22: 45658 | H22: SAY: How: FileScan, BroadcastHashJoin, SortMergeJoin, HashAggregate, Shuffle. WholeStageCodegen. Compare with Spark UI SQL tab. | I22: https://spark.apache.org/docs/latest/sql-performance-tuning.html
A23: 15 | B23: Query Engine Internals | C23: Adaptive Query Execution (AQE) in Databricks | D23: High | E23: Completed | F23: 45292 | G23: 45992 | H23: SAY: On by default. Runtime coalescing, dynamic join strategy, skew handling. Demo: join that becomes broadcast after stats. Don't disable without reason. | I23: https://docs.databricks.com/en/optimizations/aqe.html
A24: Lakeflow
A25: 16 | B25: Lakeflow | C25: Lakeflow Declarative Pipelines (DLT) concepts | D25: Medium | E25: In Progress | F25: 45901 | H25: SAY: Declarative medallion: @dlt.table, expectations (warn/drop/fail). Streaming + batch unified. Replaces some handwritten MERGE orchestration. Also called DLT; rebranded Lakeflow Declarative Pipelines. | I25: https://docs.databricks.com/en/delta-live-tables/index.html
A26: 17 | B26: Lakeflow | C26: Lakeflow Jobs orchestration | D26: Medium | E26: In Progress | F26: 45901 | H26: SAY: Workflows/Jobs: multi-task DAG, retries, alerts, job clusters. ADF can still trigger Databricks jobs via API. For Databricks-native, Jobs > dbutils.notebook.run in prod. | I26: https://docs.databricks.com/en/workflows/jobs/index.html
A27: Medallion Architecture
A28: 18 | B28: Medallion Architecture | C28: Bronze layer concepts | D28: High | E28: Completed | F28: 44713 | G28: 45261 | H28: SAY: Raw, append-only, source-aligned. Keep original payload + audit cols (load_ts, source_file, batch_id). No business cleanses. Replayable. | I28: https://www.databricks.com/glossary/medallion-architecture
A29: 19 | B29: Medallion Architecture | C29: Silver layer concepts | D29: High | E29: Completed | F29: 44713 | G29: 45444 | H29: SAY: Cleaned, typed, deduped, conformed. SCD2 for entities. DQ rules. Joinable enterprise tables. MERGE from Bronze using business keys. | I29: https://www.databricks.com/glossary/medallion-architecture
A30: 20 | B30: Medallion Architecture | C30: Gold layer concepts | D30: High | E30: Completed | F30: 44713 | G30: 45444 | H30: SAY: Business-ready stars/aggregates, KPIs, marts for Power BI/Synapse. Grain documented. Incremental refresh friendly. Conformed dims. | I30: https://www.databricks.com/glossary/medallion-architecture
A31: Data Ingestion (Important)
A32: 21 | B32: Data Ingestion (Important) | C32: Auto Loader / incremental ingestion patterns | D32: High | E32: Completed | F32: 45078 | G32: 45809 | H32: SAY: cloudFiles source: incrementally ingest new files, schema inference/evolution, RocksDB/JSON checkpoint. Better than directory listing. Use with notification mode at scale. | I32: https://docs.databricks.com/en/ingestion/auto-loader/index.html
A33: 22 | B33: Data Ingestion (Important) | C33: Batch vs streaming ingestion in Databricks | D33: High | E33: Completed | F33: 45078 | G33: 45809 | H33: SAY: Batch: scheduled read of a date partition. Streaming: Auto Loader / Event Hub continuous. Same Delta MERGE into Silver. Trigger AvailableNow = batch-like streaming for daily loads. | I33: https://docs.databricks.com/en/structured-streaming/index.html
A34: Governance & Orchestration
A35: 23 | B35: Governance & Orchestration | C35: Unity Catalog (governance, access control, lineage) | D35: High | E35: In Progress | F35: 45658 | H35: SAY: Three-level namespace catalog.schema.table. GRANT on catalogs/schemas/tables. Lineage in UI. Replaces hive_metastore for new work. Column masking for PII. Interview must-mention for 2026 Databricks roles. | I35: https://docs.databricks.com/en/data-governance/unity-catalog/index.html
A36: 24 | B36: Governance & Orchestration | C36: Databricks Workflows / Jobs orchestration | D36: High | E36: Completed | F36: 45078 | G36: 45809 | H36: SAY: Multi-task job: Bronze notebook → Silver → Gold with dependencies. Retries, timeout, email/webhook. Trigger from ADF or schedule. YAML/DABs for CI. | I36: https://docs.databricks.com/en/workflows/index.html
A37: 25 | B37: Governance & Orchestration | C37: Delta Live Tables expectations (data quality rules) | D37: Medium | E37: In Progress | F37: 45809 | H37: SAY: expect(), expect_or_drop(), expect_or_fail() on constraints (not null, valid codes). Metrics in event log. Without DLT I do the same with filter + quarantine table + log counts. | I37: https://docs.databricks.com/en/delta-live-tables/expectations.html
A38: 26 | B38: Governance & Orchestration | C38: Repos & Git integration / CI-CD basics | D38: High | E38: Completed | F38: 45078 | G38: 45992 | H38: SAY: Databricks Repos ↔ Azure DevOps/GitHub. Feature branch, PR, deploy via Azure DevOps pipeline or Databricks Asset Bundles to target workspace. Never edit prod notebooks by hand. | I38: https://docs.databricks.com/en/repos/index.html
A39: 27 | B39: Governance & Orchestration | C39: Cluster Policies & Photon engine | D39: Medium | E39: In Progress | F39: 45658 | H39: SAY: Policies restrict instance types/cost for governance. Photon = C++ vectorized engine for SQL/Delta, faster scans/joins, extra DBU. I enable Photon on job clusters when SQL-heavy. | I39: https://docs.databricks.com/en/compute/photon.html
A40: 28 | B40: Governance & Orchestration | C40: Delta Sharing | D40: Low | E40: In Progress | F40: 45809 | H40: SAY: Open protocol to share Delta tables with external orgs without copying. Unity Catalog managed shares. Alternative to extracting CSV for partners. | I40: https://docs.databricks.com/en/data-sharing/index.html
A41: 29 | B41: Governance & Orchestration | C41: Secrets management (Key Vault integration) | D41: High | E41: Completed | F41: 44927 | G41: 45627 | H41: SAY: Never hardcode secrets. Databricks secret scope backed by Azure Key Vault. dbutils.secrets.get. ADF linked services use KV too. Rotate passwords without changing code. | I41: https://docs.databricks.com/en/security/secrets/secret-scopes.html
...

Sheet Project
A1: Project
A2: End-to-end ingestion pipeline: SQL Server -> ADF -> ADLS Gen2 -> Databricks -> Bronze/Silver/Gold
A4: # | B4: Topic Area | C4: Subtopic / Concept | D4: Priority | E4: Status | F4: Date Started | G4: Date Completed | H4: Notes / Key Learnings | I4: Resource / Link
A5: Pipeline Overview
A6: 1 | B6: Pipeline Overview | C6: SQL Server -> ADF -> ADLS Gen2 -> Databricks -> Bronze -> Silver -> Gold | D6: High | E6: Completed | F6: 44713 | G6: 45809 | H6: YOUR STORY (Amdocs / US Cellular): Oracle Order Management + billing tables → extract (cron/Python or ADF Copy + SHIR) → land raw → clean/reconcile stuck orders → serve ops/BI. Domain: telecom orders, backlog, SLA. YOU owned: reconciliation ETL, PL/SQL bulk fixes, HTML run reports. METRICS YOU MAY SAY: ~60% less manual recon, 50%+ faster critical SQL. Do NOT invent '50 source tables' as your count — that is an interview design question. | I6: https://learn.microsoft.com/azure/data-factory/tutorial-hybrid-copy-powershell
A7: Source & Orchestration
A8: 2 | B8: Source & Orchestration | C8: ADF pipeline design & linked services | D8: High | E8: Completed | F8: 44713 | G8: 45658 | H8: MAP TO USCC: Linked service = Oracle (SHIR if on-prem) + ADLS + Databricks + Key Vault. Dataset parameterized by table name. Your real analog: Oracle connection + Python extract config, not 50 ADF pipelines. Azure interview: one template pipeline, many linked datasets. | I8: https://learn.microsoft.com/azure/data-factory/concepts-linked-services
A9: 3 | B9: Source & Orchestration | C9: ADF orchestration (triggers, pipelines, activities) | D9: High | E9: Completed | F9: 44713 | G9: 45658 | H9: YOUR ANALOG: Linux cron + Python jobs + Sendmail reports (Amdocs). Azure words: schedule trigger = cron; Copy = extract; Stored Proc = PL/SQL bulk fix; Notebook = transform; If/ForEach = config-driven table list. Triggers: daily batch for orders, not streaming unless asked. | I9: https://learn.microsoft.com/azure/data-factory/concepts-pipelines-activities
