Workbook

Sheet Dashboard
A1: Data Engineering Learning Tracker
A2: Overall progress dashboard — auto-calculated from each topic sheet
A4: Module | B4: Total Topics | C4: Completed | D4: In Progress | E4: Not Started | F4: % Complete
A5: SQL | B5: =COUNTA(SQL!$B$5:$B$60) | C5: =COUNTIF(SQL!$E$5:$E$60,"Completed") | D5: =COUNTIF(SQL!$E$5:$E$60,"In Progress") | E5: =COUNTIF(SQL!$E$5:$E$60,"Not Started")+COUNTIF(SQL!$E$5:$E$60,"Revise Again") | F5: =IFERROR(C5/B5,0)
A6: Data Warehouse | B6: =COUNTA('Data Warehouse'!$B$5:$B$38) | C6: =COUNTIF('Data Warehouse'!$E$5:$E$38,"Completed") | D6: =COUNTIF('Data Warehouse'!$E$5:$E$38,"In Progress") | E6: =COUNTIF('Data Warehouse'!$E$5:$E$38,"Not Started")+COUNTIF('Data Warehouse'!$E$5:$E$38,"Revise Again") | F6: =IFERROR(C6/B6,0)
A7: PySpark | B7: =COUNTA(PySpark!$B$5:$B$44) | C7: =COUNTIF(PySpark!$E$5:$E$44,"Completed") | D7: =COUNTIF(PySpark!$E$5:$E$44,"In Progress") | E7: =COUNTIF(PySpark!$E$5:$E$44,"Not Started")+COUNTIF(PySpark!$E$5:$E$44,"Revise Again") | F7: =IFERROR(C7/B7,0)
A8: Databricks | B8: =COUNTA(Databricks!$B$5:$B$41) | C8: =COUNTIF(Databricks!$E$5:$E$41,"Completed") | D8: =COUNTIF(Databricks!$E$5:$E$41,"In Progress") | E8: =COUNTIF(Databricks!$E$5:$E$41,"Not Started")+COUNTIF(Databricks!$E$5:$E$41,"Revise Again") | F8: =IFERROR(C8/B8,0)
A9: Project | B9: =COUNTA(Project!$B$5:$B$36) | C9: =COUNTIF(Project!$E$5:$E$36,"Completed") | D9: =COUNTIF(Project!$E$5:$E$36,"In Progress") | E9: =COUNTIF(Project!$E$5:$E$36,"Not Started")+COUNTIF(Project!$E$5:$E$36,"Revise Again") | F9: =IFERROR(C9/B9,0)
A10: Interview Essentials | B10: =COUNTA('Interview Essentials'!$B$5:$B$26) | C10: =COUNTIF('Interview Essentials'!$E$5:$E$26,"Completed") | D10: =COUNTIF('Interview Essentials'!$E$5:$E$26,"In Progress") | E10: =COUNTIF('Interview Essentials'!$E$5:$E$26,"Not Started")+COUNTIF('Interview Essentials'!$E$5:$E$26,"Revise Again") | F10: =IFERROR(C10/B10,0)
A11: OVERALL | B11: =SUM(B5:B10) | C11: =SUM(C5:C10) | D11: =SUM(D5:D10) | E11: =SUM(E5:E10) | F11: =IFERROR(C11/B11,0)
A14: Daily SQL Practice Snapshot
A15: Total Practice Days Logged: | C15: ='Daily SQL Practice Log'!C67
A16: Total Queries Solved: | C16: ='Daily SQL Practice Log'!C68
A17: Days Target Met (5-10 queries): | C17: ='Daily SQL Practice Log'!C69
A20: How to use this tracker
A21: 1. Go to each topic tab (SQL, Data Warehouse, PySpark, Databricks, Project, Interview Essentials) and update the 'Status' dropdown as you learn each subtopic.
A22: 2. Use 'Priority' to flag High/Medium/Low so you know what to focus on next.
A23: 3. Fill 'Date Started', 'Date Completed', 'Notes / Key Learnings', and 'Resource / Link' as you go.
A24: 4. Log daily SQL practice (5-10 queries) in the 'Daily SQL Practice Log' tab — it auto-flags whether you hit the target.
A25: 5. This Dashboard auto-updates counts and % complete per module from the Status columns — no manual editing needed here (except cells with formulas may be viewed only).

Sheet SQL
A1: SQL
A2: Basics -> Window Functions -> Aggregations -> Joins -> Query Optimization -> SCD -> CDC -> EXISTS -> MERGE
B3: HakerRank | C3: CodeChef
A4: # | B4: Topic Area | C4: Subtopic / Concept | D4: Priority | E4: Status | F4: Date Started | G4: Date Completed | H4: Notes / Key Learnings | I4: Resource / Link
A5: Basics
A6: 1 | B6: Basics | C6: SELECT, WHERE, ORDER BY, DISTINCT, LIMIT/TOP | D6: Low | E6: Completed | H6: Core filtering/sorting. LIMIT/TOP/FETCH FIRST syntax differs by DB (MySQL/Postgres vs SQL Server/Oracle).
A7: 2 | B7: Basics | C7: Filtering: IN, BETWEEN, LIKE, IS NULL | D7: Low | E7: Completed | H7: IN for discrete sets, BETWEEN inclusive ranges, LIKE with %/_ wildcards, IS NULL (never = NULL since NULL isn't comparable).
A8: 3 | B8: Basics | C8: GROUP BY and HAVING | D8: Low | E8: Completed | H8: GROUP BY aggregates rows; HAVING filters after aggregation (WHERE filters before). Every non-aggregated SELECT column must be in GROUP BY.
A9: 4 | B9: Basics | C9: Data types, constraints, basic DDL/DML | D9: Low | E9: Completed | H9: DDL: CREATE/ALTER/DROP define structure. DML: INSERT/UPDATE/DELETE modify data. Constraints: PK, FK, UNIQUE, CHECK, NOT NULL, DEFAULT.
A10: Aggregations
A11: 5 | B11: Aggregations | C11: COUNT, SUM, AVG, MIN, MAX | D11: Low | E11: Completed | H11: COUNT(*) counts rows incl NULLs; COUNT(col) excludes NULLs. Aggregates ignore NULLs by default in SUM/AVG.
A12: 6 | B12: Aggregations | C12: GROUP BY with multiple columns | D12: Low | E12: Completed | H12: Groups form on every unique combination of listed columns; order affects grouping granularity, not aggregation result.
A13: 7 | B13: Aggregations | C13: ROLLUP, CUBE, GROUPING SETS | D13: Medium | E13: Completed | H13: ROLLUP gives hierarchical subtotals (e.g. year>month>total); CUBE gives all combinations; GROUPING SETS lets you define custom subtotal combos explicitly.
A14: Joins
A15: 8 | B15: Joins | C15: INNER JOIN | D15: Low | E15: Completed | H15: Returns only matching rows in both tables based on join condition.
A16: 9 | B16: Joins | C16: LEFT / RIGHT JOIN | D16: Low | E16: Completed | H16: LEFT keeps all left rows + matched right (NULLs if no match); RIGHT is mirror. Prefer LEFT JOIN everywhere for readability.
A17: 10 | B17: Joins | C17: FULL OUTER JOIN | D17: Low | E17: Completed | H17: Returns all rows from both sides, NULLs where no match; MySQL lacks native support, emulate via LEFT UNION RIGHT.
A18: 11 | B18: Joins | C18: SELF JOIN | D18: Medium | E18: Completed | H18: Table joined to itself using aliases; used for hierarchies (employee-manager), sequential comparisons.
A19: 12 | B19: Joins | C19: CROSS JOIN | D19: Low | E19: Completed | H19: Cartesian product of two tables (no join condition) — rows_A x rows_B. Used for combinatorial generation.
A20: 13 | B20: Joins | C20: Anti-join / Semi-join patterns (NOT EXISTS, NOT IN) | D20: High | E20: Completed | H20: NOT EXISTS/LEFT JOIN...IS NULL for anti-join (rows with no match). Prefer NOT EXISTS over NOT IN since NOT IN breaks on NULLs in subquery.
A21: Window Functions
A22: 14 | B22: Window Functions | C22: ROW_NUMBER, RANK, DENSE_RANK | D22: High | E22: Completed | H22: ROW_NUMBER: unique sequential rank, no ties. RANK: ties share rank, gaps after. DENSE_RANK: ties share rank, no gaps. Classic dedup pattern: ROW_NUMBER() OVER(PARTITION BY key ORDER BY ts DESC)=1.
A23: 15 | B23: Window Functions | C23: LEAD, LAG | D23: High | E23: Completed | H23: Access next/previous row's value within a partition without self-join; used for period-over-period comparisons, gap analysis.
A24: 16 | B24: Window Functions | C24: SUM/AVG OVER (PARTITION BY ... ORDER BY ...) | D24: High | E24: Completed | H24: Window aggregation keeps row-level detail while adding aggregate context (e.g. % of category total).
A25: 17 | B25: Window Functions | C25: Running totals & moving averages | D25: High | E25: Completed | H25: Running total: SUM(x) OVER(ORDER BY date ROWS BETWEEN UNBOUNDED PRECEDING AND CURRENT ROW). Moving avg: bound the frame to N preceding rows.
A26: 18 | B26: Window Functions | C26: NTILE, FIRST_VALUE, LAST_VALUE | D26: Medium | E26: Completed | H26: NTILE(n) buckets rows into n equal groups (percentiles/quartiles). FIRST_VALUE/LAST_VALUE need explicit frame clause or LAST_VALUE returns current row only.
A27: Query Optimization
A28: 19 | B28: Query Optimization | C28: Reading execution/query plans | D28: High | E28: Completed | H28: EXPLAIN/EXPLAIN ANALYZE shows join order, scan type (seq vs index), estimated vs actual rows, cost — used to spot missing indexes and bad estimates.
A29: 20 | B29: Query Optimization | C29: Index usage basics | D29: High | E29: Completed | H29: Indexes speed up WHERE/JOIN/ORDER BY on selective columns at the cost of write overhead and storage; composite index column order matters (leftmost prefix rule).
A30: 21 | B30: Query Optimization | C30: Avoiding SELECT *, sargable predicates | D30: Medium | E30: Completed | H30: SELECT * prevents covering-index use and wastes I/O. Sargable = predicate can use an index (avoid wrapping indexed column in a function, e.g. WHERE YEAR(date)=2024).
A31: 22 | B31: Query Optimization | C31: CTE vs subquery vs temp table performance | D31: Medium | E31: Completed | H31: CTE: readability, usually inlined by optimizer (not materialized unless recursive/hinted). Subquery: similar, can be correlated. Temp table: materialized with stats, better for reuse across multiple large queries.
A32: SCD Types
A33: 23 | B33: SCD Types | C33: SCD Type 0, 1, 2, 3 concepts | D33: High | E33: Completed | H33: Type0: never changes. Type1: overwrite (no history). Type2: new row per change with effective_start/end + is_current flag (full history). Type3: extra column for previous value only (limited history).
A34: 24 | B34: SCD Types | C34: Implementing SCD Type 2 with SQL | D34: High | E34: Completed | H34: MERGE: expire current row (set end_date, is_current=0) when a tracked attribute changes, then INSERT new row with new surrogate key and is_current=1.
A35: CDC
A36: 25 | B36: CDC | C36: Change Data Capture concepts | D36: High | E36: Completed | H36: Captures inserts/updates/deletes from source since last sync, so downstream only processes deltas instead of full reload.
A37: 26 | B37: CDC | C37: CDC implementation patterns (timestamp/log-based) | D37: High | E37: Completed | H37: Timestamp-based: filter on updated_at/watermark (misses hard deletes). Log-based (e.g. SQL Server CDC/Debezium): reads transaction log, captures all DML including deletes, near real-time.
A38: EXISTS
A39: 27 | B39: EXISTS | C39: EXISTS vs IN vs JOIN performance | D39: High | E39: Completed | H39: EXISTS stops at first match (good for large subqueries, handles NULLs safely). IN materializes full list. JOIN needed when you also need columns from the other table; can duplicate rows on 1:many.
A40: MERGE
...

Sheet Data Warehouse
A1: Data Warehouse
A2: Fact/Dim, Star & Snowflake Schema, Keys, OLAP vs OLTP, ETL/ELT concepts
B3: BigQuery | C3: Snowflake | D3: Azure - Synapse
A4: # | B4: Topic Area | C4: Subtopic / Concept | D4: Priority | E4: Status | F4: Date Started | G4: Date Completed | H4: Notes / Key Learnings | I4: Resource / Link
A5: Fact & Dimension Tables
A6: 1 | B6: Fact & Dimension Tables | C6: Fact table concepts (grain, measures) | D6: High | E6: Completed | H6: Grain = level of detail one row represents (e.g. one row per order line); measures are the numeric, additive facts (qty, amount).
A7: 2 | B7: Fact & Dimension Tables | C7: Dimension table concepts (attributes, hierarchies) | D7: High | E7: Completed | H7: Descriptive context for facts (who/what/where/when); hierarchies (e.g. Day>Month>Quarter>Year) enable drill-down/roll-up.
A8: 3 | B8: Fact & Dimension Tables | C8: Types of fact tables (transactional, snapshot, accumulating) | D8: Medium | E8: Completed | H8: Transactional: one row per event. Periodic snapshot: state at fixed intervals (e.g. daily balances). Accumulating snapshot: one row per process instance, updated as it progresses through milestones.
A9: Schema Design
A10: 4 | B10: Schema Design | C10: Star Schema | D10: High | E10: Completed | H10: Central fact table directly joined to denormalized dimension tables; simple, fast for BI queries, some redundancy in dims.
A11: 5 | B11: Schema Design | C11: Snowflake Schema | D11: Medium | E11: Completed | H11: Dimensions normalized into sub-dimensions (e.g. Product->Category->Department); saves space, more joins, slightly slower queries.
A12: 6 | B12: Schema Design | C12: Star vs Snowflake trade-offs | D12: Medium | E12: Completed | H12: Star: query simplicity/performance. Snowflake: storage efficiency/data integrity. Most modern warehouses (columnar, cheap storage) favor star schema.
A13: Keys
A14: 7 | B14: Keys | C14: Primary Key | D14: Low | E14: Completed | H14: Uniquely identifies each row; not null, one per table (can be composite).
A15: 8 | B15: Keys | C15: Foreign Key | D15: Low | E15: Completed | H15: Column(s) referencing a PK in another table, enforcing referential integrity between fact and dimension.
A16: 9 | B16: Keys | C16: Surrogate Key vs Natural Key | D16: High | E16: Completed | H16: Surrogate key: system-generated (e.g. identity/int), stable, used in warehouse to support SCD2/history. Natural key: business meaningful key from source, can change or be reused.
A17: 10 | B17: Keys | C17: Composite Key | D17: Low | E17: Completed | H17: Primary key made of multiple columns together uniquely identifying a row (common in junction/bridge tables).
A18: OLAP vs OLTP
A19: 11 | B19: OLAP vs OLTP | C19: OLTP characteristics | D19: Medium | E19: Completed | H19: Normalized schema, many small fast read/write transactions, optimized for consistency (e.g. order processing systems).
A20: 12 | B20: OLAP vs OLTP | C20: OLAP characteristics | D20: Medium | E20: Completed | H20: Denormalized/dimensional schema, optimized for large read-heavy analytical aggregation queries over historical data.
A21: 13 | B21: OLAP vs OLTP | C21: Use case differences | D21: Low | E21: Completed | H21: OLTP = operational day-to-day systems; OLAP = reporting/analytics/BI on top of aggregated historical data.
A22: ETL Concepts
A23: 14 | B23: ETL Concepts | C23: ETL vs ELT | D23: High | E23: Completed | H23: ETL: transform before loading into target (transform in staging/engine). ELT: load raw first, transform inside the warehouse/lake (leverages scalable compute like Spark/Snowflake) — dominant pattern in modern cloud stacks.
A24: 15 | B24: ETL Concepts | C24: Full Load | D24: Low | E24: Completed | H24: Reload entire dataset each run; simple but expensive for large tables, used for small/reference data or first load.
A25: 16 | B25: ETL Concepts | C25: Incremental Load | D25: High | E25: Completed | H25: Load only new/changed records since last run, using watermark column (updated_at) or CDC; reduces processing time and cost.
A26: 17 | B26: ETL Concepts | C26: Batch Processing mode | D26: Low | E26: Completed | H26: Data processed in scheduled chunks/intervals (hourly/daily) rather than continuously.
A27: 18 | B27: ETL Concepts | C27: Streaming mode | D27: Medium | E27: Completed | H27: Data processed continuously/near real-time as it arrives (e.g. Spark Structured Streaming, Kafka).
A28: Modeling Approaches
A29: 19 | B29: Modeling Approaches | C29: Kimball (bottom-up) vs Inmon (top-down) | D29: Medium | E29: Completed | H29: Kimball: build dimensional data marts first, bottom-up, faster time to value, conformed dimensions link marts. Inmon: build normalized enterprise DW first (3NF), then derive marts, top-down, more consistency but slower.
A30: 20 | B30: Modeling Approaches | C30: Conceptual, Logical, Physical data models | D30: Low | E30: Completed | H30: Conceptual: high-level business entities/relationships. Logical: attributes, keys, normalization, DB-agnostic. Physical: actual tables/columns/types/indexes for a specific engine.
A31: 21 | B31: Modeling Approaches | C31: Data Mart vs Data Warehouse | D31: Low | E31: Completed | H31: Data warehouse: enterprise-wide integrated store. Data mart: subject/department-specific subset (e.g. Sales mart), often sourced from the warehouse.
A32: Advanced Dimension Concepts
A33: 22 | B33: Advanced Dimension Concepts | C33: Conformed Dimension | D33: Medium | E33: Completed | H33: Shared dimension (e.g. Date, Customer) used consistently across multiple fact tables/marts, enabling cross-subject-area analysis.
A34: 23 | B34: Advanced Dimension Concepts | C34: Junk Dimension | D34: Medium | E34: Completed | H34: Combines several low-cardinality flags/indicators (e.g. yes/no fields) into a single dimension table to avoid many tiny dims in the fact table.
A35: 24 | B35: Advanced Dimension Concepts | C35: Degenerate Dimension | D35: Medium | E35: Completed | H35: Dimension-like attribute stored directly in the fact table with no separate dimension table (e.g. invoice/order number).
A36: 25 | B36: Advanced Dimension Concepts | C36: Slowly Changing Dimension Type 3, 4, 6 (hybrid) | D36: Medium | E36: Completed | H36: Type3: extra 'previous value' column (limited history). Type4: separate history table + current table. Type6 (hybrid 1+2+3): combines overwrite, new-row history, and previous-value column.
A37: Advanced Fact Concepts
A38: 26 | B38: Advanced Fact Concepts | C38: Factless Fact Table | D38: Medium | E38: Completed | H38: Fact table with no measures, just keys — captures events/relationships (e.g. student attended class) or coverage (what didn't happen).
A40: EXAMPLE (for reference only — edit/delete before use): Topic Area: Schema Design | Subtopic: Star Schema | Priority: High | Status: Completed | Notes: Understood denormalized dims joined directly to fact table; drew sample schema for retail sales.

Sheet PySpark
A1: PySpark
A2: In-depth architecture, DataFrame fundamentals, joins, and performance tuning
A4: # | B4: Topic Area | C4: Subtopic / Concept | D4: Priority | E4: Status | F4: Date Started | G4: Date Completed | H4: Notes / Key Learnings | I4: Resource / Link
A5: Architecture
A6: 1 | B6: Architecture | C6: Driver, Executor, Cluster Manager overview | D6: High | E6: Completed | H6: Driver: runs main program, builds DAG, schedules tasks. Executors: run tasks, store data in memory/disk. Cluster manager (YARN/Standalone/Kubernetes) allocates resources across the cluster.
A7: 2 | B7: Architecture | C7: How an application runs in the backend (submission to execution) | D7: High | E7: Completed | H7: spark-submit -> driver starts SparkContext -> requests executors from cluster manager -> driver builds DAG from transformations -> DAG split into stages/tasks -> tasks sent to executors -> results returned to driver.
A8: 3 | B8: Architecture | C8: Job -> Stages -> Tasks breakdown | D8: High | E8: Completed | H8: Action triggers a Job. Job split into Stages at shuffle boundaries. Each stage split into Tasks, one per partition, run in parallel on executors.
A9: 4 | B9: Architecture | C9: Lazy Evaluation & DAG | D9: High | E9: Completed | H9: Transformations (map/filter/select) build a logical DAG without executing; execution only triggered by an Action (collect/count/write), allowing Catalyst/Spark to optimize the whole plan first.
A10: File Formats
A11: 5 | B11: File Formats | C11: CSV | D11: Low | E11: Completed | H11: Row-based, human-readable, no schema/type enforcement by default, slower to read/write, no compression/columnar pruning — fine for small/interchange data only.
A12: 6 | B12: File Formats | C12: Parquet | D12: High | E12: Completed | H12: Columnar, compressed, schema embedded, supports predicate/column pushdown — default and preferred format for Spark/Databricks pipelines.
A13: 7 | B13: File Formats | C13: AVRO | D13: Medium | E13: Completed | H13: Row-based binary format with schema evolution support, common for Kafka/streaming ingestion (schema registry compatibility).
A14: DataFrame Fundamentals
A15: 8 | B15: DataFrame Fundamentals | C15: Creating & transforming DataFrames | D15: Low | E15: Completed | H15: Create via spark.read, spark.createDataFrame, or SQL; transform via select/filter/withColumn/groupBy chains that build the logical plan.
A16: 9 | B16: DataFrame Fundamentals | C16: Common transformations (select, filter, withColumn, groupBy) | D16: Low | E16: Completed | H16: select projects columns, filter/where subsets rows, withColumn adds/modifies a column, groupBy+agg aggregates — all lazy transformations.
A17: 10 | B17: DataFrame Fundamentals | C17: Actions vs Transformations | D17: High | E17: Completed | H17: Transformations are lazy (return new DataFrame, build DAG): select/filter/join. Actions trigger execution and return results/write output: count/collect/show/write.
A18: Joins
A19: 11 | B19: Joins | C19: Broadcast Hash Join | D19: High | E19: Completed | H19: Small table broadcast in full to every executor, avoids shuffle; used automatically when one side is below spark.sql.autoBroadcastJoinThreshold (default 10MB).
A20: 12 | B20: Joins | C20: Sort Merge Join | D20: High | E20: Completed | H20: Default for large-large joins; both sides shuffled and sorted on join key, then merged — expensive due to shuffle+sort.
A21: 13 | B21: Joins | C21: Shuffle Hash Join | D21: Medium | E21: Completed | H21: Builds a hash table on the smaller side per partition after shuffle, no sort needed; used when broadcast isn't possible but one side is still moderately smaller.
A22: Performance Tuning
A23: 14 | B23: Performance Tuning | C23: Partitioning | D23: High | E23: Completed | H23: Data split into partitions processed in parallel; too few partitions underutilizes cluster, too many adds scheduling overhead — tune with repartition/spark.sql.shuffle.partitions.
A24: 15 | B24: Performance Tuning | C24: Repartition vs Coalesce | D24: High | E24: Completed | H24: repartition: full shuffle, can increase or decrease partitions, even distribution. coalesce: no/minimal shuffle, only decreases partitions, can cause uneven sizes — use coalesce before writing to reduce small files cheaply.
A25: 16 | B25: Performance Tuning | C25: Shuffle operations | D25: High | E25: Completed | H25: Data movement across executors/network for wide transformations (groupBy, join, distinct, repartition) — most expensive Spark operation, minimize where possible.
A26: 17 | B26: Performance Tuning | C26: Cardinality | D26: Medium | E26: Completed | H26: Number of distinct values in a column; high cardinality (e.g. user_id) is good for join/partition keys, low cardinality (e.g. gender) risks skew if used for partitioning.
A27: 18 | B27: Performance Tuning | C27: Data Skew & handling techniques (salting) | D27: High | E27: Completed | H27: Skew: uneven data distribution across partitions causes some tasks to take much longer. Salting: append random suffix to skewed key, join, then aggregate/strip suffix, to spread load evenly. AQE skew join handling also helps automatically.
A28: 19 | B28: Performance Tuning | C28: Broadcast variables/joins | D28: High | E28: Completed | H28: Broadcast variable: read-only value cached on each executor once (avoids re-sending per task). Broadcast join uses this for small-table joins to avoid shuffle.
A29: 20 | B29: Performance Tuning | C29: Predicate Pushdown | D29: Medium | E29: Completed | H29: Filters pushed down to the data source (e.g. Parquet file scan) so only needed rows are read, reducing I/O.
A30: 21 | B30: Performance Tuning | C30: Caching vs Persistence (storage levels) | D30: Medium | E30: Completed | H30: cache() = persist with default MEMORY_AND_DISK. persist() lets you choose storage level (MEMORY_ONLY, MEMORY_AND_DISK, DISK_ONLY, with/without serialization) — use when a DataFrame is reused across multiple actions.
A31: 22 | B31: Performance Tuning | C31: Serialization (Kryo vs Java) | D31: Low | E31: Completed | H31: Java serialization is default, flexible but slow/large. Kryo is faster and more compact, recommended for production (spark.serializer=KryoSerializer) but needs classes registered for best performance.
A32: 23 | B32: Performance Tuning | C32: Adaptive Query Execution (AQE) | D32: High | E32: Completed | H32: Runtime re-optimization: dynamically coalesces shuffle partitions, switches sort-merge to broadcast join when actual size is small, and splits skewed partitions — enabled by default in modern Spark.
A33: 24 | B33: Performance Tuning | C33: Small file problem & solutions | D33: High | E33: Completed | H33: Too many tiny files from frequent small writes (esp. streaming) hurts read performance due to overhead per file. Fix: coalesce/repartition before write, Delta OPTIMIZE (compaction), Auto Loader file consolidation.
A34: Core Concepts
A35: 25 | B35: Core Concepts | C35: RDD vs DataFrame vs Dataset | D35: Medium | E35: Completed | H35: RDD: low-level, no schema, no Catalyst optimization. DataFrame: schema-aware, Catalyst+Tungsten optimized, untyped (Python/SQL). Dataset: DataFrame + compile-time type safety (JVM languages only, not available in PySpark).
A36: 26 | B36: Core Concepts | C36: Spark SQL basics | D36: Low | E36: Completed | H36: Run SQL directly on DataFrames registered as temp views (createOrReplaceTempView) via spark.sql(); compiles to same Catalyst plan as DataFrame API.
A37: 27 | B37: Core Concepts | C37: UDFs & Pandas UDFs (and their performance cost) | D37: High | E37: Completed | H37: Regular UDFs: row-by-row, break Catalyst optimization, serialize data to Python process (slow). Pandas UDFs (vectorized, Arrow-based): operate on batches, much faster — always prefer built-in functions first, then Pandas UDF over regular UDF.
A38: 28 | B38: Core Concepts | C38: Cluster deployment modes (client vs cluster) | D38: Low | E38: Completed | H38: Client mode: driver runs on the machine that submitted the job (good for interactive/notebooks). Cluster mode: driver runs inside the cluster (good for production jobs, resilient to submitting-machine disconnect).
A39: 29 | B39: Core Concepts | C39: Memory management (execution vs storage memory, spill) | D39: Medium | E39: Completed | H39: Unified memory split between execution (shuffles/joins/sorts) and storage (caching), can borrow from each other. Spill: when data exceeds memory, Spark writes to disk, slowing performance.
A40: 30 | B40: Core Concepts | C40: Checkpointing | D40: Medium | E40: Completed | H40: Truncates the lineage DAG by saving DataFrame to reliable storage, used to avoid recomputation for long iterative jobs and required for streaming stateful operations.
A41: 31 | B41: Core Concepts | C41: Reading the Spark UI (DAG, stages, tasks, shuffle) | D41: High | E41: Completed | H41: Spark UI shows Jobs > Stages > Tasks, DAG visualization, shuffle read/write sizes, task duration skew — primary tool for diagnosing slow/skewed stages.
...

Sheet Databricks
A1: Databricks
A2: Delta tables, compute, optimization techniques, Catalyst internals, Lakeflow, Medallion architecture
A4: # | B4: Topic Area | C4: Subtopic / Concept | D4: Priority | E4: Status | F4: Date Started | G4: Date Completed | H4: Notes / Key Learnings | I4: Resource / Link
A5: Delta Tables (Important)
A6: 1 | B6: Delta Tables (Important) | C6: Delta Lake fundamentals (transaction log, ACID) | D6: High | E6: Completed | H6: Delta = Parquet + transaction log (_delta_log) of JSON commits, giving ACID transactions, versioning, and consistent reads/writes on the lake.
A7: 2 | B7: Delta Tables (Important) | C7: Time Travel & versioning | D7: High | E7: Completed | H7: Query prior table state via VERSION AS OF / TIMESTAMP AS OF, using the transaction log — useful for audits, rollback, reproducing pipeline runs.
A8: 3 | B8: Delta Tables (Important) | C8: Schema evolution & enforcement | D8: High | E8: Completed | H8: Enforcement: writes rejected if schema mismatches by default (prevents bad data). Evolution: mergeSchema/overwriteSchema options allow adding new columns intentionally during writes.
A9: Compute & Notebooks
A10: 4 | B10: Compute & Notebooks | C10: Notebooks basics & widgets | D10: Low | E10: Completed | H10: Databricks notebooks support multi-language cells (%python/%sql/%scala); widgets create parameterized input controls (dropdown/text) for interactive or job-driven notebooks.
A11: 5 | B11: Compute & Notebooks | C11: Cluster types (All-purpose, Job, SQL Warehouse) | D11: Medium | E11: Completed | H11: All-purpose: interactive dev, shared, more expensive. Job cluster: spun up per job run, terminates after, cheaper for scheduled pipelines. SQL Warehouse: optimized compute for SQL/BI queries.
A12: 6 | B12: Compute & Notebooks | C12: Cluster sizing & autoscaling | D12: Medium | E12: Completed | H12: Autoscaling adjusts worker count within min/max based on load; right-size node type/count based on workload (memory-heavy vs compute-heavy) to balance cost and performance.
A13: Delta Optimization
A14: 7 | B14: Delta Optimization | C14: OPTIMIZE (compaction / Z-Ordering) | D14: High | E14: Completed | H14: OPTIMIZE compacts small files into larger ones for faster reads. Z-ORDER co-locates related data by specified columns, improving data skipping for filtered queries.
A15: 8 | B15: Delta Optimization | C15: VACUUM | D15: High | E15: Completed | H15: Removes old data files no longer referenced by the transaction log, beyond retention period (default 7 days) — needed to control storage cost, but disables time travel beyond that window.
A16: 9 | B16: Delta Optimization | C16: Liquid Clustering | D16: Medium | E16: Completed | H16: Newer alternative to partitioning/Z-Ordering — flexible, incremental clustering on chosen columns without rewriting the whole table or fixed partition scheme.
A17: 10 | B17: Delta Optimization | C17: Bucketing | D17: Low | E17: Completed | H17: Pre-shuffles/organizes data into a fixed number of buckets by hash of a column to speed up joins/aggregations on that column; less relevant with Liquid Clustering/AQE in modern Databricks.
A18: 11 | B18: Delta Optimization | C18: Predictive Optimization | D18: Low | E18: Completed | H18: Databricks-managed feature that automatically runs OPTIMIZE/VACUUM/ANALYZE on Unity Catalog tables based on usage patterns, without manual scheduling.
A19: Query Engine Internals
A20: 12 | B20: Query Engine Internals | C20: Catalyst Optimizer overview | D20: High | E20: Completed | H20: Spark's query optimizer: parses SQL/DataFrame code into an unresolved logical plan, resolves it, applies rule-based optimizations, generates physical plans, picks the best via cost model, then generates code (Tungsten).
A21: 13 | B21: Query Engine Internals | C21: Logical Plan | D21: Medium | E21: Completed | H21: Abstract, engine-independent representation of what the query should do (before deciding how) — unresolved then resolved/optimized logical plan stages.
A22: 14 | B22: Query Engine Internals | C22: Physical Plan | D22: Medium | E22: Completed | H22: Concrete execution strategy chosen by Catalyst (e.g. which join algorithm, scan type) from multiple candidate physical plans based on cost.
A23: 15 | B23: Query Engine Internals | C23: Adaptive Query Execution (AQE) in Databricks | D23: High | E23: Completed | H23: Same AQE as OSS Spark, enabled by default on Databricks: dynamic partition coalescing, join strategy switching, and skew handling at runtime based on actual stats.
A24: Lakeflow
A25: 16 | B25: Lakeflow | C25: Lakeflow Declarative Pipelines (DLT) concepts | D25: High | E25: Completed | H25: Declarative framework (formerly Delta Live Tables) where you define tables/transformations and Databricks manages orchestration, dependency graph, incremental processing, and data quality checks.
A26: 17 | B26: Lakeflow | C26: Lakeflow Jobs orchestration | D26: Medium | E26: Completed | H26: Databricks-native orchestrator for scheduling and chaining notebooks/tasks/pipelines with dependencies, retries, alerts — alternative to external orchestrators like Airflow for Databricks-centric workflows.
A27: Medallion Architecture
A28: 18 | B28: Medallion Architecture | C28: Bronze layer concepts | D28: High | E28: Completed | H28: Raw, ingested-as-is data from source systems, minimal transformation, includes audit/metadata columns — source of truth for reprocessing.
A29: 19 | B29: Medallion Architecture | C29: Silver layer concepts | D29: High | E29: Completed | H29: Cleaned, validated, deduplicated, conformed data — business-level entities with quality rules applied, joins across sources.
A30: 20 | B30: Medallion Architecture | C30: Gold layer concepts | D30: High | E30: Completed | H30: Curated, aggregated, business-ready tables (star schema/metrics) consumed directly by BI tools and downstream analytics.
A31: Data Ingestion (Important)
A32: 21 | B32: Data Ingestion (Important) | C32: Auto Loader / incremental ingestion patterns | D32: High | E32: Completed | H32: Incrementally and efficiently processes new files landing in cloud storage using cloudFiles source, with schema inference/evolution and checkpointed exactly-once processing — avoids re-listing entire directories.
A33: 22 | B33: Data Ingestion (Important) | C33: Batch vs streaming ingestion in Databricks | D33: Medium | E33: Completed | H33: Batch: scheduled full/incremental reads (e.g. via ADF trigger + notebook). Streaming: Auto Loader/Structured Streaming continuously ingests new files/events with low latency.
A34: Governance & Orchestration
A35: 23 | B35: Governance & Orchestration | C35: Unity Catalog (governance, access control, lineage) | D35: High | E35: Completed | H35: Centralized governance layer across workspaces: fine-grained access control (table/row/column level), automatic data lineage, unified catalog for all data/AI assets.
A36: 24 | B36: Governance & Orchestration | C36: Databricks Workflows / Jobs orchestration | D36: Medium | E36: Completed | H36: Native scheduler for multi-task jobs with dependencies, retries, alerting, parameterization — commonly used to orchestrate Bronze->Silver->Gold notebook chains.
A37: 25 | B37: Governance & Orchestration | C37: Delta Live Tables expectations (data quality rules) | D37: Medium | E37: Completed | H37: Declarative constraints (expect, expect_or_drop, expect_or_fail) applied to DLT tables to validate/quarantine/fail records that violate data quality rules, with metrics tracked automatically.
A38: 26 | B38: Governance & Orchestration | C38: Repos & Git integration / CI-CD basics | D38: Medium | E38: Completed | H38: Databricks Repos sync notebooks with Git providers for version control, branching, PR-based review; combined with CI/CD (Azure DevOps/GitHub Actions) to deploy code/jobs across environments.
A39: 27 | B39: Governance & Orchestration | C39: Cluster Policies & Photon engine | D39: Medium | E39: Completed | H39: Cluster policies restrict/standardize cluster configs (cost control, compliance). Photon is Databricks' native vectorized query engine (C++ based) that accelerates SQL/DataFrame workloads.
A40: 28 | B40: Governance & Orchestration | C40: Delta Sharing | D40: Low | E40: Completed | H40: Open protocol to securely share live Delta tables across organizations/platforms without copying data or vendor lock-in.
A41: 29 | B41: Governance & Orchestration | C41: Secrets management (Key Vault integration) | D41: Medium | E41: Completed | H41: Databricks secret scopes backed by Azure Key Vault store credentials (connection strings, API keys) securely, referenced in notebooks without hardcoding.
...

Sheet Project
A1: Project
A2: End-to-end ingestion pipeline: SQL Server -> ADF -> ADLS Gen2 -> Databricks -> Bronze/Silver/Gold
A4: # | B4: Topic Area | C4: Subtopic / Concept | D4: Priority | E4: Status | F4: Date Started | G4: Date Completed | H4: Notes / Key Learnings | I4: Resource / Link
A5: Pipeline Overview
A6: 1 | B6: Pipeline Overview | C6: SQL Server -> ADF -> ADLS Gen2 -> Databricks -> Bronze -> Silver -> Gold | D6: High | E6: Completed | H6: End-to-end flow: ADF extracts from SQL Server into raw zone in ADLS Gen2 -> Databricks ingests to Bronze (raw Delta) -> cleans/dedupes to Silver -> aggregates/models to Gold for BI.
A7: Source & Orchestration
A8: 2 | B8: Source & Orchestration | C8: ADF pipeline design & linked services | D8: High | E8: Completed | H8: Linked services define connections to source/sink (SQL Server, ADLS); pipelines chain activities (Copy, Databricks notebook, lookup) into a repeatable workflow.
A9: 3 | B9: Source & Orchestration | C9: ADF orchestration (triggers, pipelines, activities) | D9: High | E9: Completed | H9: Triggers: schedule, tumbling window, or event-based pipeline runs. Pipelines group activities (Copy, ExecuteNotebook, ForEach, If Condition) into a logical unit of work.
A10: 4 | B10: Source & Orchestration | C10: Landing raw data into ADLS Gen2 | D10: Medium | E10: Completed | H10: ADF Copy activity lands source extracts as files (Parquet/CSV) into a raw/landing zone in ADLS Gen2, partitioned by date/batch for traceability.
A11: Load Patterns
A12: 5 | B12: Load Patterns | C12: Full Load implementation | D12: Medium | E12: Completed | H12: Truncate/reload entire source table each run — simplest, used for small dimension/reference tables.
A13: 6 | B13: Load Patterns | C13: Incremental Load implementation (watermarking) | D13: High | E13: Completed | H13: Track a watermark (max updated_at or ID) per table in a control table; each run pulls only rows greater than the last watermark and updates it after success.
A14: 7 | B14: Load Patterns | C14: Metadata-driven ingestion framework | D14: High | E14: Completed | H14: A control/config table (source, target, watermark column, load type) drives a generic ADF pipeline via lookup + ForEach, so new sources are onboarded by adding config rows, not new pipelines.
A15: Bronze Layer
A16: 8 | B16: Bronze Layer | C16: Raw data ingestion into Delta (Bronze) | D16: High | E16: Completed | H16: Land source files as-is into Delta format Bronze tables, preserving original structure/values for full reprocessing capability.
A17: 9 | B17: Bronze Layer | C17: Audit columns (load timestamp, source, batch id) | D17: High | E17: Completed | H17: Standard metadata columns added at ingestion (_load_ts, _source_system, _batch_id, _file_name) for traceability, debugging, and reprocessing.
A18: 10 | B18: Bronze Layer | C18: Logging & error handling during ingestion | D18: High | E18: Completed | H18: Wrap ingestion in try/except with structured logging (row counts, failures) to a log table/Log Analytics; bad records routed to a quarantine table rather than failing the whole pipeline.
A19: Silver Layer
A20: 11 | B20: Silver Layer | C20: Data quality checks & validation rules | D20: High | E20: Completed | H20: Silver-layer checks: null checks on required fields, type/range validation, referential integrity, row count reconciliation — failing records quarantined, passing records promoted.
A21: 12 | B21: Silver Layer | C21: Deduplication logic | D21: High | E21: Completed | H21: ROW_NUMBER() OVER(PARTITION BY business_key ORDER BY updated_at DESC)=1 to keep latest record per key; or dropDuplicates() with a defined key set.
A22: 13 | B22: Silver Layer | C22: SCD Type 2 implementation | D22: High | E22: Completed | H22: MERGE-based pattern: expire matched-but-changed current rows (set end_date/is_current=0), insert new versions with surrogate key, effective_start_date, is_current=1.
A23: 14 | B23: Silver Layer | C23: Delta MERGE for upserts | D23: High | E23: Completed | H23: MERGE INTO target USING source ON key WHEN MATCHED THEN UPDATE WHEN NOT MATCHED THEN INSERT — core mechanism for Silver upserts and SCD2 in Delta.
A24: Gold Layer
A25: 15 | B25: Gold Layer | C25: Curated / aggregated business tables | D25: Medium | E25: Completed | H25: Gold layer builds business-facing aggregates/metrics (e.g. daily sales by region) joining Silver tables, ready for direct BI consumption.
A26: 16 | B26: Gold Layer | C26: Star schema modeling in Gold layer | D26: High | E26: Completed | H26: Gold layer organized as fact + dimension tables optimized for BI tool query performance and business-friendly naming.
A27: Cross-Cutting Concerns
A28: 17 | B28: Cross-Cutting Concerns | C28: End-to-end error handling strategy | D28: High | E28: Completed | H28: Layered approach: retries for transient failures, try/except with quarantine tables for bad data, pipeline-level alerting on failure, idempotent reruns.
A29: 18 | B29: Cross-Cutting Concerns | C29: Centralized logging framework | D29: Medium | E29: Completed | H29: Common logging function/utility used across notebooks writing structured logs (pipeline, status, row counts, error message, timestamp) to a shared log table or Log Analytics workspace.
A30: 19 | B30: Cross-Cutting Concerns | C30: Audit column standards across layers | D30: Medium | E30: Completed | H30: Consistent metadata columns (_load_ts, _source_system, _batch_id, _is_current, _updated_ts) carried and enriched from Bronze through Gold for lineage and debugging.
A31: 20 | B31: Cross-Cutting Concerns | C31: Schema drift / schema evolution handling | D31: High | E31: Completed | H31: Auto Loader/Delta mergeSchema handles new columns automatically; alerting on unexpected type changes or dropped columns to avoid silent data loss.
A32: 21 | B32: Cross-Cutting Concerns | C32: Parameterization & dynamic pipelines in ADF | D32: High | E32: Completed | H32: Pipeline/dataset parameters + lookup activities allow one generic pipeline to process many tables/sources driven by a config table, avoiding pipeline sprawl.
A33: 22 | B33: Cross-Cutting Concerns | C33: Monitoring & alerting (Azure Monitor, Log Analytics) | D33: Medium | E33: Completed | H33: ADF/Databricks metrics and logs pushed to Log Analytics; alert rules on pipeline failures, SLA breaches, or data quality thresholds notify via email/Teams.
A34: 23 | B34: Cross-Cutting Concerns | C34: Secrets management (Azure Key Vault) in ADF/Databricks | D34: Medium | E34: Completed | H34: Connection strings/credentials stored in Key Vault, referenced via ADF Key Vault linked service or Databricks secret scopes — never hardcoded in pipelines/notebooks.
A35: 24 | B35: Cross-Cutting Concerns | C35: CI/CD for data pipelines (Azure DevOps) | D35: Medium | E35: Completed | H35: ADF ARM templates and Databricks notebooks/repos version-controlled in Git, deployed across dev/test/prod via Azure DevOps release pipelines with environment-specific parameters.
A36: 25 | B36: Cross-Cutting Concerns | C36: Unit/data testing for pipelines | D36: Medium | E36: Completed | H36: pytest/chispa for transformation logic unit tests on sample DataFrames; row count and reconciliation checks between source and target as data tests.
A38: EXAMPLE (for reference only — edit/delete before use): Topic Area: Silver Layer | Subtopic: SCD Type 2 implementation | Priority: High | Status: In Progress | Notes: Built MERGE-based SCD2 logic with effective_start_date/effective_end_date/is_current flags.

Sheet Interview Essentials
A1: Interview Essentials
A2: Cross-cutting skills often missed but commonly tested: Git, Python, Cloud, Governance, Testing/CI-CD, Monitoring
A4: # | B4: Topic Area | C4: Subtopic / Concept | D4: Priority | E4: Status | F4: Date Started | G4: Date Completed | H4: Notes / Key Learnings | I4: Resource / Link
A5: Git & Version Control
A6: 1 | B6: Git & Version Control | C6: Branching, merge/rebase, pull requests | D6: High | E6: Completed | H6: Feature branches off main, PR-based review before merge; rebase for a clean linear history, merge to preserve branch history — know how to resolve conflicts.
A7: Python for Data Engineering
A8: 2 | B8: Python for Data Engineering | C8: Python fundamentals (functions, OOP basics, list/dict comprehensions) | D8: High | E8: Completed | H8: Comfortable with functions/decorators, basic OOP (classes, inheritance), and comprehensions for concise data transforms — commonly used in PySpark UDFs and utility scripts.
A9: 3 | B9: Python for Data Engineering | C9: Working with APIs, JSON, file I/O | D9: Medium | E9: Completed | H9: requests library for REST API calls, json module/pandas for parsing nested JSON, standard file I/O for reading/writing local files during ingestion utilities.
A10: Cloud Fundamentals (Azure)
A11: 4 | B11: Cloud Fundamentals (Azure) | C11: Azure Storage (Blob/ADLS Gen2) basics | D11: High | E11: Completed | H11: ADLS Gen2 = Blob storage + hierarchical namespace, enabling directory-level operations and finer ACLs; standard landing/raw zone for the lakehouse.
A12: 5 | B12: Cloud Fundamentals (Azure) | C12: Azure SQL / Synapse basics | D12: Medium | E12: Completed | H12: Azure SQL DB: managed OLTP database. Synapse: unified analytics (SQL pool for MPP warehousing + Spark pool), used for large-scale warehouse/ELT workloads.
A13: 6 | B13: Cloud Fundamentals (Azure) | C13: Azure Key Vault & IAM/RBAC basics | D13: Medium | E13: Completed | H13: Key Vault centrally stores secrets/keys/certs. RBAC assigns least-privilege roles at resource scope (subscription/resource group/resource) to users/service principals/managed identities.
A14: Data Governance & Security
A15: 7 | B15: Data Governance & Security | C15: Data governance concepts (lineage, cataloging) | D15: Medium | E15: Completed | H15: Lineage tracks data flow from source to consumption for impact analysis/debugging; cataloging (e.g. Unity Catalog, Purview) makes datasets discoverable with metadata/ownership.
A16: 8 | B16: Data Governance & Security | C16: Data masking / PII handling | D16: Medium | E16: Completed | H16: Column-level masking/dynamic data masking hides sensitive fields for non-privileged roles; tokenization/hashing for PII at rest, access enforced via Unity Catalog/RBAC.
A17: 9 | B17: Data Governance & Security | C17: Encryption at rest & in transit | D17: Low | E17: Completed | H17: At rest: storage-level encryption (e.g. Azure Storage Service Encryption). In transit: TLS/HTTPS for data movement between services — mostly managed by cloud provider by default.
A18: Testing & CI/CD
A19: 10 | B19: Testing & CI/CD | C19: Unit testing for data pipelines (pytest, chispa, etc.) | D19: Medium | E19: Completed | H19: pytest for transformation function logic; chispa for asserting PySpark DataFrame equality; test with small synthetic DataFrames rather than full production data.
A20: 11 | B20: Testing & CI/CD | C20: CI/CD pipelines for data engineering (Azure DevOps/GitHub Actions) | D20: Medium | E20: Completed | H20: Automated build/test/deploy of notebooks, ADF ARM templates, and job configs across dev/test/prod on merge to main, with approval gates for prod.
A21: Monitoring & Cost
A22: 12 | B22: Monitoring & Cost | C22: Pipeline monitoring & alerting | D22: Medium | E22: Completed | H22: Track pipeline run status, duration, row counts; alert on failures/SLA breaches via Azure Monitor/Log Analytics + email/Teams/PagerDuty integration.
A23: 13 | B23: Monitoring & Cost | C23: Cost optimization (cluster sizing, spot instances, autoscaling) | D23: Medium | E23: Completed | H23: Right-size clusters to workload, use job clusters (not all-purpose) for scheduled jobs, spot/preemptible instances for fault-tolerant workloads, autoscaling to avoid idle compute.
A24: Interview Prep
A25: 14 | B25: Interview Prep | C25: System design for data pipelines (whiteboard a pipeline end-to-end) | D25: High | E25: In Progress | H25: Practice articulating: source -> ingestion (batch/stream) -> raw/bronze -> transform/quality -> silver -> model/aggregate -> gold -> serving, plus orchestration, monitoring, and failure handling at each stage.
A26: 15 | B26: Interview Prep | C26: Behavioral questions (STAR method) for DE roles | D26: High | E26: In Progress | H26: Prepare 4-5 STAR stories (Situation, Task, Action, Result) covering: a production incident you fixed, a performance optimization, a conflict/collaboration, and a project you led end-to-end.
A28: EXAMPLE (for reference only — edit/delete before use): Topic Area: Data Governance & Security | Subtopic: Data masking / PII handling | Priority: Medium | Status: Not Started | Notes: Review Databricks column-level masking with Unity Catalog.

Sheet Daily SQL Practice Log
A1: Daily SQL Practice Log
A2: Track daily practice of 5-10 SQL queries — log every session here
A4: Date | B4: Queries Solved | C4: Target Met? (5-10) | D4: Topics Practiced | E4: Difficulty Level | F4: Platform / Source | G4: Confidence (1-5) | H4: Notes
C5: =IF(B5="","",IF(AND(B5>=5,B5<=10),"Yes","No"))
C6: =IF(B6="","",IF(AND(B6>=5,B6<=10),"Yes","No"))
C7: =IF(B7="","",IF(AND(B7>=5,B7<=10),"Yes","No"))
C8: =IF(B8="","",IF(AND(B8>=5,B8<=10),"Yes","No"))
C9: =IF(B9="","",IF(AND(B9>=5,B9<=10),"Yes","No"))
C10: =IF(B10="","",IF(AND(B10>=5,B10<=10),"Yes","No"))
C11: =IF(B11="","",IF(AND(B11>=5,B11<=10),"Yes","No"))
C12: =IF(B12="","",IF(AND(B12>=5,B12<=10),"Yes","No"))
C13: =IF(B13="","",IF(AND(B13>=5,B13<=10),"Yes","No"))
C14: =IF(B14="","",IF(AND(B14>=5,B14<=10),"Yes","No"))
C15: =IF(B15="","",IF(AND(B15>=5,B15<=10),"Yes","No"))
C16: =IF(B16="","",IF(AND(B16>=5,B16<=10),"Yes","No"))
... C64: =IF(B64="","",IF(AND(B64>=5,B64<=10),"Yes","No"))
A67: Total Practice Days Logged: | C67: =COUNT(A5:A64)
A68: Total Queries Solved: | C68: =SUM(B5:B64)
A69: Days Target Met (5-10 queries): | C69: =COUNTIF(C5:C64,"Yes")
A70: Average Confidence: | C70: =IFERROR(AVERAGE(G5:G64),0)
A72: EXAMPLE (for reference only — edit/delete before use): 2026-08-22 | 7 queries | Window Functions, Joins | Medium | LeetCode | Confidence 3 | Notes: Struggled with multi-partition LEAD/LAG, need more practice.
